Watching for file changes with StatReloader
[12/Aug/2025 11:02:03] "GET /app/cv_hub/entries/ HTTP/1.1" 200 36884
[12/Aug/2025 11:02:03] "GET /api/cv_hub/states/ HTTP/1.1" 200 254
Internal Server Error: /api/cv_hub/entries/
Traceback (most recent call last):
  File "/Users/dealshare/anaconda3/lib/python3.11/site-packages/django/db/backends/utils.py", line 105, in _execute
    return self.cursor.execute(sql, params)
           ^^^^^^^^^^^^^^^^^^^^^^^^^^^^^^^^
psycopg2.errors.UndefinedColumn: column cv_hub_cvhubgstregistration.created_by_id does not exist
LINE 1: ...primary", "cv_hub_cvhubgstregistration"."status", "cv_hub_cv...
                                                             ^


The above exception was the direct cause of the following exception:

Traceback (most recent call last):
  File "/Users/dealshare/anaconda3/lib/python3.11/site-packages/django/core/handlers/exception.py", line 55, in inner
    response = get_response(request)
               ^^^^^^^^^^^^^^^^^^^^^
  File "/Users/dealshare/anaconda3/lib/python3.11/site-packages/django/core/handlers/base.py", line 197, in _get_response
    response = wrapped_callback(request, *callback_args, **callback_kwargs)
               ^^^^^^^^^^^^^^^^^^^^^^^^^^^^^^^^^^^^^^^^^^^^^^^^^^^^^^^^^^^^
  File "/Users/dealshare/anaconda3/lib/python3.11/site-packages/django/views/decorators/csrf.py", line 65, in _view_wrapper
    return view_func(request, *args, **kwargs)
           ^^^^^^^^^^^^^^^^^^^^^^^^^^^^^^^^^^^
  File "/Users/dealshare/anaconda3/lib/python3.11/site-packages/rest_framework/viewsets.py", line 125, in view
    return self.dispatch(request, *args, **kwargs)
           ^^^^^^^^^^^^^^^^^^^^^^^^^^^^^^^^^^^^^^^
  File "/Users/dealshare/anaconda3/lib/python3.11/site-packages/rest_framework/views.py", line 515, in dispatch
    response = self.handle_exception(exc)
               ^^^^^^^^^^^^^^^^^^^^^^^^^^
  File "/Users/dealshare/anaconda3/lib/python3.11/site-packages/rest_framework/views.py", line 475, in handle_exception
    self.raise_uncaught_exception(exc)
  File "/Users/dealshare/anaconda3/lib/python3.11/site-packages/rest_framework/views.py", line 486, in raise_uncaught_exception
    raise exc
  File "/Users/dealshare/anaconda3/lib/python3.11/site-packages/rest_framework/views.py", line 512, in dispatch
    response = handler(request, *args, **kwargs)
               ^^^^^^^^^^^^^^^^^^^^^^^^^^^^^^^^^
  File "/Users/dealshare/anaconda3/lib/python3.11/site-packages/rest_framework/mixins.py", line 40, in list
    page = self.paginate_queryset(queryset)
           ^^^^^^^^^^^^^^^^^^^^^^^^^^^^^^^^
  File "/Users/dealshare/anaconda3/lib/python3.11/site-packages/rest_framework/generics.py", line 175, in paginate_queryset
    return self.paginator.paginate_queryset(queryset, self.request, view=self)
           ^^^^^^^^^^^^^^^^^^^^^^^^^^^^^^^^^^^^^^^^^^^^^^^^^^^^^^^^^^^^^^^^^^^
  File "/Users/dealshare/anaconda3/lib/python3.11/site-packages/rest_framework/pagination.py", line 222, in paginate_queryset
    return list(self.page)
           ^^^^^^^^^^^^^^^
  File "/Users/dealshare/anaconda3/lib/python3.11/site-packages/django/core/paginator.py", line 191, in __len__
    return len(self.object_list)
           ^^^^^^^^^^^^^^^^^^^^^
  File "/Users/dealshare/anaconda3/lib/python3.11/site-packages/django/db/models/query.py", line 366, in __len__
    self._fetch_all()
  File "/Users/dealshare/anaconda3/lib/python3.11/site-packages/django/db/models/query.py", line 1951, in _fetch_all
    self._prefetch_related_objects()
  File "/Users/dealshare/anaconda3/lib/python3.11/site-packages/django/db/models/query.py", line 1328, in _prefetch_related_objects
    prefetch_related_objects(self._result_cache, *self._prefetch_related_lookups)
  File "/Users/dealshare/anaconda3/lib/python3.11/site-packages/django/db/models/query.py", line 2397, in prefetch_related_objects
    obj_list, additional_lookups = prefetch_one_level(
                                   ^^^^^^^^^^^^^^^^^^^
  File "/Users/dealshare/anaconda3/lib/python3.11/site-packages/django/db/models/query.py", line 2561, in prefetch_one_level
    ) = prefetcher.get_prefetch_querysets(
        ^^^^^^^^^^^^^^^^^^^^^^^^^^^^^^^^^^
  File "/Users/dealshare/anaconda3/lib/python3.11/site-packages/django/db/models/fields/related_descriptors.py", line 800, in get_prefetch_querysets
    for rel_obj in queryset:
  File "/Users/dealshare/anaconda3/lib/python3.11/site-packages/django/db/models/query.py", line 384, in __iter__
    self._fetch_all()
  File "/Users/dealshare/anaconda3/lib/python3.11/site-packages/django/db/models/query.py", line 1949, in _fetch_all
    self._result_cache = list(self._iterable_class(self))
                         ^^^^^^^^^^^^^^^^^^^^^^^^^^^^^^^^
  File "/Users/dealshare/anaconda3/lib/python3.11/site-packages/django/db/models/query.py", line 91, in __iter__
    results = compiler.execute_sql(
              ^^^^^^^^^^^^^^^^^^^^^
  File "/Users/dealshare/anaconda3/lib/python3.11/site-packages/django/db/models/sql/compiler.py", line 1623, in execute_sql
    cursor.execute(sql, params)
  File "/Users/dealshare/anaconda3/lib/python3.11/site-packages/django/db/backends/utils.py", line 122, in execute
    return super().execute(sql, params)
           ^^^^^^^^^^^^^^^^^^^^^^^^^^^^
  File "/Users/dealshare/anaconda3/lib/python3.11/site-packages/django/db/backends/utils.py", line 79, in execute
    return self._execute_with_wrappers(
           ^^^^^^^^^^^^^^^^^^^^^^^^^^^^
  File "/Users/dealshare/anaconda3/lib/python3.11/site-packages/django/db/backends/utils.py", line 92, in _execute_with_wrappers
    return executor(sql, params, many, context)
           ^^^^^^^^^^^^^^^^^^^^^^^^^^^^^^^^^^^^
  File "/Users/dealshare/anaconda3/lib/python3.11/site-packages/django/db/backends/utils.py", line 100, in _execute
    with self.db.wrap_database_errors:
  File "/Users/dealshare/anaconda3/lib/python3.11/site-packages/django/db/utils.py", line 91, in __exit__
    raise dj_exc_value.with_traceback(traceback) from exc_value
  File "/Users/dealshare/anaconda3/lib/python3.11/site-packages/django/db/backends/utils.py", line 105, in _execute
    return self.cursor.execute(sql, params)
           ^^^^^^^^^^^^^^^^^^^^^^^^^^^^^^^^
django.db.utils.ProgrammingError: column cv_hub_cvhubgstregistration.created_by_id does not exist
LINE 1: ...primary", "cv_hub_cvhubgstregistration"."status", "cv_hub_cv...
                                                             ^

[12/Aug/2025 11:02:03] "GET /api/cv_hub/entries/?page=1 HTTP/1.1" 500 197003
[12/Aug/2025 11:02:03] "GET /app/cv_hub/entries/ HTTP/1.1" 200 36884
[12/Aug/2025 11:02:04] "GET /api/cv_hub/states/ HTTP/1.1" 200 254
Internal Server Error: /api/cv_hub/entries/
Traceback (most recent call last):
  File "/Users/dealshare/anaconda3/lib/python3.11/site-packages/django/db/backends/utils.py", line 105, in _execute
    return self.cursor.execute(sql, params)
           ^^^^^^^^^^^^^^^^^^^^^^^^^^^^^^^^
psycopg2.errors.UndefinedColumn: column cv_hub_cvhubgstregistration.created_by_id does not exist
LINE 1: ...primary", "cv_hub_cvhubgstregistration"."status", "cv_hub_cv...
                                                             ^


The above exception was the direct cause of the following exception:

Traceback (most recent call last):
  File "/Users/dealshare/anaconda3/lib/python3.11/site-packages/django/core/handlers/exception.py", line 55, in inner
    response = get_response(request)
               ^^^^^^^^^^^^^^^^^^^^^
  File "/Users/dealshare/anaconda3/lib/python3.11/site-packages/django/core/handlers/base.py", line 197, in _get_response
    response = wrapped_callback(request, *callback_args, **callback_kwargs)
               ^^^^^^^^^^^^^^^^^^^^^^^^^^^^^^^^^^^^^^^^^^^^^^^^^^^^^^^^^^^^
  File "/Users/dealshare/anaconda3/lib/python3.11/site-packages/django/views/decorators/csrf.py", line 65, in _view_wrapper
    return view_func(request, *args, **kwargs)
           ^^^^^^^^^^^^^^^^^^^^^^^^^^^^^^^^^^^
  File "/Users/dealshare/anaconda3/lib/python3.11/site-packages/rest_framework/viewsets.py", line 125, in view
    return self.dispatch(request, *args, **kwargs)
           ^^^^^^^^^^^^^^^^^^^^^^^^^^^^^^^^^^^^^^^
  File "/Users/dealshare/anaconda3/lib/python3.11/site-packages/rest_framework/views.py", line 515, in dispatch
    response = self.handle_exception(exc)
               ^^^^^^^^^^^^^^^^^^^^^^^^^^
  File "/Users/dealshare/anaconda3/lib/python3.11/site-packages/rest_framework/views.py", line 475, in handle_exception
    self.raise_uncaught_exception(exc)
  File "/Users/dealshare/anaconda3/lib/python3.11/site-packages/rest_framework/views.py", line 486, in raise_uncaught_exception
    raise exc
  File "/Users/dealshare/anaconda3/lib/python3.11/site-packages/rest_framework/views.py", line 512, in dispatch
    response = handler(request, *args, **kwargs)
               ^^^^^^^^^^^^^^^^^^^^^^^^^^^^^^^^^
  File "/Users/dealshare/anaconda3/lib/python3.11/site-packages/rest_framework/mixins.py", line 40, in list
    page = self.paginate_queryset(queryset)
           ^^^^^^^^^^^^^^^^^^^^^^^^^^^^^^^^
  File "/Users/dealshare/anaconda3/lib/python3.11/site-packages/rest_framework/generics.py", line 175, in paginate_queryset
    return self.paginator.paginate_queryset(queryset, self.request, view=self)
           ^^^^^^^^^^^^^^^^^^^^^^^^^^^^^^^^^^^^^^^^^^^^^^^^^^^^^^^^^^^^^^^^^^^
  File "/Users/dealshare/anaconda3/lib/python3.11/site-packages/rest_framework/pagination.py", line 222, in paginate_queryset
    return list(self.page)
           ^^^^^^^^^^^^^^^
  File "/Users/dealshare/anaconda3/lib/python3.11/site-packages/django/core/paginator.py", line 191, in __len__
    return len(self.object_list)
           ^^^^^^^^^^^^^^^^^^^^^
  File "/Users/dealshare/anaconda3/lib/python3.11/site-packages/django/db/models/query.py", line 366, in __len__
    self._fetch_all()
  File "/Users/dealshare/anaconda3/lib/python3.11/site-packages/django/db/models/query.py", line 1951, in _fetch_all
    self._prefetch_related_objects()
  File "/Users/dealshare/anaconda3/lib/python3.11/site-packages/django/db/models/query.py", line 1328, in _prefetch_related_objects
    prefetch_related_objects(self._result_cache, *self._prefetch_related_lookups)
  File "/Users/dealshare/anaconda3/lib/python3.11/site-packages/django/db/models/query.py", line 2397, in prefetch_related_objects
    obj_list, additional_lookups = prefetch_one_level(
                                   ^^^^^^^^^^^^^^^^^^^
  File "/Users/dealshare/anaconda3/lib/python3.11/site-packages/django/db/models/query.py", line 2561, in prefetch_one_level
    ) = prefetcher.get_prefetch_querysets(
        ^^^^^^^^^^^^^^^^^^^^^^^^^^^^^^^^^^
  File "/Users/dealshare/anaconda3/lib/python3.11/site-packages/django/db/models/fields/related_descriptors.py", line 800, in get_prefetch_querysets
    for rel_obj in queryset:
  File "/Users/dealshare/anaconda3/lib/python3.11/site-packages/django/db/models/query.py", line 384, in __iter__
    self._fetch_all()
  File "/Users/dealshare/anaconda3/lib/python3.11/site-packages/django/db/models/query.py", line 1949, in _fetch_all
    self._result_cache = list(self._iterable_class(self))
                         ^^^^^^^^^^^^^^^^^^^^^^^^^^^^^^^^
  File "/Users/dealshare/anaconda3/lib/python3.11/site-packages/django/db/models/query.py", line 91, in __iter__
    results = compiler.execute_sql(
              ^^^^^^^^^^^^^^^^^^^^^
  File "/Users/dealshare/anaconda3/lib/python3.11/site-packages/django/db/models/sql/compiler.py", line 1623, in execute_sql
    cursor.execute(sql, params)
  File "/Users/dealshare/anaconda3/lib/python3.11/site-packages/django/db/backends/utils.py", line 122, in execute
    return super().execute(sql, params)
           ^^^^^^^^^^^^^^^^^^^^^^^^^^^^
  File "/Users/dealshare/anaconda3/lib/python3.11/site-packages/django/db/backends/utils.py", line 79, in execute
    return self._execute_with_wrappers(
           ^^^^^^^^^^^^^^^^^^^^^^^^^^^^
  File "/Users/dealshare/anaconda3/lib/python3.11/site-packages/django/db/backends/utils.py", line 92, in _execute_with_wrappers
    return executor(sql, params, many, context)
           ^^^^^^^^^^^^^^^^^^^^^^^^^^^^^^^^^^^^
  File "/Users/dealshare/anaconda3/lib/python3.11/site-packages/django/db/backends/utils.py", line 100, in _execute
    with self.db.wrap_database_errors:
  File "/Users/dealshare/anaconda3/lib/python3.11/site-packages/django/db/utils.py", line 91, in __exit__
    raise dj_exc_value.with_traceback(traceback) from exc_value
  File "/Users/dealshare/anaconda3/lib/python3.11/site-packages/django/db/backends/utils.py", line 105, in _execute
    return self.cursor.execute(sql, params)
           ^^^^^^^^^^^^^^^^^^^^^^^^^^^^^^^^
django.db.utils.ProgrammingError: column cv_hub_cvhubgstregistration.created_by_id does not exist
LINE 1: ...primary", "cv_hub_cvhubgstregistration"."status", "cv_hub_cv...
                                                             ^

[12/Aug/2025 11:02:04] "GET /api/cv_hub/entries/?page=1 HTTP/1.1" 500 197003
[12/Aug/2025 11:02:04] "GET /app/cv_hub/entries/ HTTP/1.1" 200 36884
[12/Aug/2025 11:02:04] "GET /api/cv_hub/states/ HTTP/1.1" 200 254
Internal Server Error: /api/cv_hub/entries/
Traceback (most recent call last):
  File "/Users/dealshare/anaconda3/lib/python3.11/site-packages/django/db/backends/utils.py", line 105, in _execute
    return self.cursor.execute(sql, params)
           ^^^^^^^^^^^^^^^^^^^^^^^^^^^^^^^^
psycopg2.errors.UndefinedColumn: column cv_hub_cvhubgstregistration.created_by_id does not exist
LINE 1: ...primary", "cv_hub_cvhubgstregistration"."status", "cv_hub_cv...
                                                             ^


The above exception was the direct cause of the following exception:

Traceback (most recent call last):
  File "/Users/dealshare/anaconda3/lib/python3.11/site-packages/django/core/handlers/exception.py", line 55, in inner
    response = get_response(request)
               ^^^^^^^^^^^^^^^^^^^^^
  File "/Users/dealshare/anaconda3/lib/python3.11/site-packages/django/core/handlers/base.py", line 197, in _get_response
    response = wrapped_callback(request, *callback_args, **callback_kwargs)
               ^^^^^^^^^^^^^^^^^^^^^^^^^^^^^^^^^^^^^^^^^^^^^^^^^^^^^^^^^^^^
  File "/Users/dealshare/anaconda3/lib/python3.11/site-packages/django/views/decorators/csrf.py", line 65, in _view_wrapper
    return view_func(request, *args, **kwargs)
           ^^^^^^^^^^^^^^^^^^^^^^^^^^^^^^^^^^^
  File "/Users/dealshare/anaconda3/lib/python3.11/site-packages/rest_framework/viewsets.py", line 125, in view
    return self.dispatch(request, *args, **kwargs)
           ^^^^^^^^^^^^^^^^^^^^^^^^^^^^^^^^^^^^^^^
  File "/Users/dealshare/anaconda3/lib/python3.11/site-packages/rest_framework/views.py", line 515, in dispatch
    response = self.handle_exception(exc)
               ^^^^^^^^^^^^^^^^^^^^^^^^^^
  File "/Users/dealshare/anaconda3/lib/python3.11/site-packages/rest_framework/views.py", line 475, in handle_exception
    self.raise_uncaught_exception(exc)
  File "/Users/dealshare/anaconda3/lib/python3.11/site-packages/rest_framework/views.py", line 486, in raise_uncaught_exception
    raise exc
  File "/Users/dealshare/anaconda3/lib/python3.11/site-packages/rest_framework/views.py", line 512, in dispatch
    response = handler(request, *args, **kwargs)
               ^^^^^^^^^^^^^^^^^^^^^^^^^^^^^^^^^
  File "/Users/dealshare/anaconda3/lib/python3.11/site-packages/rest_framework/mixins.py", line 40, in list
    page = self.paginate_queryset(queryset)
           ^^^^^^^^^^^^^^^^^^^^^^^^^^^^^^^^
  File "/Users/dealshare/anaconda3/lib/python3.11/site-packages/rest_framework/generics.py", line 175, in paginate_queryset
    return self.paginator.paginate_queryset(queryset, self.request, view=self)
           ^^^^^^^^^^^^^^^^^^^^^^^^^^^^^^^^^^^^^^^^^^^^^^^^^^^^^^^^^^^^^^^^^^^
  File "/Users/dealshare/anaconda3/lib/python3.11/site-packages/rest_framework/pagination.py", line 222, in paginate_queryset
    return list(self.page)
           ^^^^^^^^^^^^^^^
  File "/Users/dealshare/anaconda3/lib/python3.11/site-packages/django/core/paginator.py", line 191, in __len__
    return len(self.object_list)
           ^^^^^^^^^^^^^^^^^^^^^
  File "/Users/dealshare/anaconda3/lib/python3.11/site-packages/django/db/models/query.py", line 366, in __len__
    self._fetch_all()
  File "/Users/dealshare/anaconda3/lib/python3.11/site-packages/django/db/models/query.py", line 1951, in _fetch_all
    self._prefetch_related_objects()
  File "/Users/dealshare/anaconda3/lib/python3.11/site-packages/django/db/models/query.py", line 1328, in _prefetch_related_objects
    prefetch_related_objects(self._result_cache, *self._prefetch_related_lookups)
  File "/Users/dealshare/anaconda3/lib/python3.11/site-packages/django/db/models/query.py", line 2397, in prefetch_related_objects
    obj_list, additional_lookups = prefetch_one_level(
                                   ^^^^^^^^^^^^^^^^^^^
  File "/Users/dealshare/anaconda3/lib/python3.11/site-packages/django/db/models/query.py", line 2561, in prefetch_one_level
    ) = prefetcher.get_prefetch_querysets(
        ^^^^^^^^^^^^^^^^^^^^^^^^^^^^^^^^^^
  File "/Users/dealshare/anaconda3/lib/python3.11/site-packages/django/db/models/fields/related_descriptors.py", line 800, in get_prefetch_querysets
    for rel_obj in queryset:
  File "/Users/dealshare/anaconda3/lib/python3.11/site-packages/django/db/models/query.py", line 384, in __iter__
    self._fetch_all()
  File "/Users/dealshare/anaconda3/lib/python3.11/site-packages/django/db/models/query.py", line 1949, in _fetch_all
    self._result_cache = list(self._iterable_class(self))
                         ^^^^^^^^^^^^^^^^^^^^^^^^^^^^^^^^
  File "/Users/dealshare/anaconda3/lib/python3.11/site-packages/django/db/models/query.py", line 91, in __iter__
    results = compiler.execute_sql(
              ^^^^^^^^^^^^^^^^^^^^^
  File "/Users/dealshare/anaconda3/lib/python3.11/site-packages/django/db/models/sql/compiler.py", line 1623, in execute_sql
    cursor.execute(sql, params)
  File "/Users/dealshare/anaconda3/lib/python3.11/site-packages/django/db/backends/utils.py", line 122, in execute
    return super().execute(sql, params)
           ^^^^^^^^^^^^^^^^^^^^^^^^^^^^
  File "/Users/dealshare/anaconda3/lib/python3.11/site-packages/django/db/backends/utils.py", line 79, in execute
    return self._execute_with_wrappers(
           ^^^^^^^^^^^^^^^^^^^^^^^^^^^^
  File "/Users/dealshare/anaconda3/lib/python3.11/site-packages/django/db/backends/utils.py", line 92, in _execute_with_wrappers
    return executor(sql, params, many, context)
           ^^^^^^^^^^^^^^^^^^^^^^^^^^^^^^^^^^^^
  File "/Users/dealshare/anaconda3/lib/python3.11/site-packages/django/db/backends/utils.py", line 100, in _execute
    with self.db.wrap_database_errors:
  File "/Users/dealshare/anaconda3/lib/python3.11/site-packages/django/db/utils.py", line 91, in __exit__
    raise dj_exc_value.with_traceback(traceback) from exc_value
  File "/Users/dealshare/anaconda3/lib/python3.11/site-packages/django/db/backends/utils.py", line 105, in _execute
    return self.cursor.execute(sql, params)
           ^^^^^^^^^^^^^^^^^^^^^^^^^^^^^^^^
django.db.utils.ProgrammingError: column cv_hub_cvhubgstregistration.created_by_id does not exist
LINE 1: ...primary", "cv_hub_cvhubgstregistration"."status", "cv_hub_cv...
                                                             ^

[12/Aug/2025 11:02:04] "GET /api/cv_hub/entries/?page=1 HTTP/1.1" 500 197003
[12/Aug/2025 11:02:04] "GET /app/cv_hub/entries/ HTTP/1.1" 200 36884
[12/Aug/2025 11:02:04] "GET /api/cv_hub/states/ HTTP/1.1" 200 254
Internal Server Error: /api/cv_hub/entries/
Traceback (most recent call last):
  File "/Users/dealshare/anaconda3/lib/python3.11/site-packages/django/db/backends/utils.py", line 105, in _execute
    return self.cursor.execute(sql, params)
           ^^^^^^^^^^^^^^^^^^^^^^^^^^^^^^^^
psycopg2.errors.UndefinedColumn: column cv_hub_cvhubgstregistration.created_by_id does not exist
LINE 1: ...primary", "cv_hub_cvhubgstregistration"."status", "cv_hub_cv...
                                                             ^


The above exception was the direct cause of the following exception:

Traceback (most recent call last):
  File "/Users/dealshare/anaconda3/lib/python3.11/site-packages/django/core/handlers/exception.py", line 55, in inner
    response = get_response(request)
               ^^^^^^^^^^^^^^^^^^^^^
  File "/Users/dealshare/anaconda3/lib/python3.11/site-packages/django/core/handlers/base.py", line 197, in _get_response
    response = wrapped_callback(request, *callback_args, **callback_kwargs)
               ^^^^^^^^^^^^^^^^^^^^^^^^^^^^^^^^^^^^^^^^^^^^^^^^^^^^^^^^^^^^
  File "/Users/dealshare/anaconda3/lib/python3.11/site-packages/django/views/decorators/csrf.py", line 65, in _view_wrapper
    return view_func(request, *args, **kwargs)
           ^^^^^^^^^^^^^^^^^^^^^^^^^^^^^^^^^^^
  File "/Users/dealshare/anaconda3/lib/python3.11/site-packages/rest_framework/viewsets.py", line 125, in view
    return self.dispatch(request, *args, **kwargs)
           ^^^^^^^^^^^^^^^^^^^^^^^^^^^^^^^^^^^^^^^
  File "/Users/dealshare/anaconda3/lib/python3.11/site-packages/rest_framework/views.py", line 515, in dispatch
    response = self.handle_exception(exc)
               ^^^^^^^^^^^^^^^^^^^^^^^^^^
  File "/Users/dealshare/anaconda3/lib/python3.11/site-packages/rest_framework/views.py", line 475, in handle_exception
    self.raise_uncaught_exception(exc)
  File "/Users/dealshare/anaconda3/lib/python3.11/site-packages/rest_framework/views.py", line 486, in raise_uncaught_exception
    raise exc
  File "/Users/dealshare/anaconda3/lib/python3.11/site-packages/rest_framework/views.py", line 512, in dispatch
    response = handler(request, *args, **kwargs)
               ^^^^^^^^^^^^^^^^^^^^^^^^^^^^^^^^^
  File "/Users/dealshare/anaconda3/lib/python3.11/site-packages/rest_framework/mixins.py", line 40, in list
    page = self.paginate_queryset(queryset)
           ^^^^^^^^^^^^^^^^^^^^^^^^^^^^^^^^
  File "/Users/dealshare/anaconda3/lib/python3.11/site-packages/rest_framework/generics.py", line 175, in paginate_queryset
    return self.paginator.paginate_queryset(queryset, self.request, view=self)
           ^^^^^^^^^^^^^^^^^^^^^^^^^^^^^^^^^^^^^^^^^^^^^^^^^^^^^^^^^^^^^^^^^^^
  File "/Users/dealshare/anaconda3/lib/python3.11/site-packages/rest_framework/pagination.py", line 222, in paginate_queryset
    return list(self.page)
           ^^^^^^^^^^^^^^^
  File "/Users/dealshare/anaconda3/lib/python3.11/site-packages/django/core/paginator.py", line 191, in __len__
    return len(self.object_list)
           ^^^^^^^^^^^^^^^^^^^^^
  File "/Users/dealshare/anaconda3/lib/python3.11/site-packages/django/db/models/query.py", line 366, in __len__
    self._fetch_all()
  File "/Users/dealshare/anaconda3/lib/python3.11/site-packages/django/db/models/query.py", line 1951, in _fetch_all
    self._prefetch_related_objects()
  File "/Users/dealshare/anaconda3/lib/python3.11/site-packages/django/db/models/query.py", line 1328, in _prefetch_related_objects
    prefetch_related_objects(self._result_cache, *self._prefetch_related_lookups)
  File "/Users/dealshare/anaconda3/lib/python3.11/site-packages/django/db/models/query.py", line 2397, in prefetch_related_objects
    obj_list, additional_lookups = prefetch_one_level(
                                   ^^^^^^^^^^^^^^^^^^^
  File "/Users/dealshare/anaconda3/lib/python3.11/site-packages/django/db/models/query.py", line 2561, in prefetch_one_level
    ) = prefetcher.get_prefetch_querysets(
        ^^^^^^^^^^^^^^^^^^^^^^^^^^^^^^^^^^
  File "/Users/dealshare/anaconda3/lib/python3.11/site-packages/django/db/models/fields/related_descriptors.py", line 800, in get_prefetch_querysets
    for rel_obj in queryset:
  File "/Users/dealshare/anaconda3/lib/python3.11/site-packages/django/db/models/query.py", line 384, in __iter__
    self._fetch_all()
  File "/Users/dealshare/anaconda3/lib/python3.11/site-packages/django/db/models/query.py", line 1949, in _fetch_all
    self._result_cache = list(self._iterable_class(self))
                         ^^^^^^^^^^^^^^^^^^^^^^^^^^^^^^^^
  File "/Users/dealshare/anaconda3/lib/python3.11/site-packages/django/db/models/query.py", line 91, in __iter__
    results = compiler.execute_sql(
              ^^^^^^^^^^^^^^^^^^^^^
  File "/Users/dealshare/anaconda3/lib/python3.11/site-packages/django/db/models/sql/compiler.py", line 1623, in execute_sql
    cursor.execute(sql, params)
  File "/Users/dealshare/anaconda3/lib/python3.11/site-packages/django/db/backends/utils.py", line 122, in execute
    return super().execute(sql, params)
           ^^^^^^^^^^^^^^^^^^^^^^^^^^^^
  File "/Users/dealshare/anaconda3/lib/python3.11/site-packages/django/db/backends/utils.py", line 79, in execute
    return self._execute_with_wrappers(
           ^^^^^^^^^^^^^^^^^^^^^^^^^^^^
  File "/Users/dealshare/anaconda3/lib/python3.11/site-packages/django/db/backends/utils.py", line 92, in _execute_with_wrappers
    return executor(sql, params, many, context)
           ^^^^^^^^^^^^^^^^^^^^^^^^^^^^^^^^^^^^
  File "/Users/dealshare/anaconda3/lib/python3.11/site-packages/django/db/backends/utils.py", line 100, in _execute
    with self.db.wrap_database_errors:
  File "/Users/dealshare/anaconda3/lib/python3.11/site-packages/django/db/utils.py", line 91, in __exit__
    raise dj_exc_value.with_traceback(traceback) from exc_value
  File "/Users/dealshare/anaconda3/lib/python3.11/site-packages/django/db/backends/utils.py", line 105, in _execute
    return self.cursor.execute(sql, params)
           ^^^^^^^^^^^^^^^^^^^^^^^^^^^^^^^^
django.db.utils.ProgrammingError: column cv_hub_cvhubgstregistration.created_by_id does not exist
LINE 1: ...primary", "cv_hub_cvhubgstregistration"."status", "cv_hub_cv...
                                                             ^

[12/Aug/2025 11:02:04] "GET /api/cv_hub/entries/?page=1 HTTP/1.1" 500 197003
[12/Aug/2025 11:02:05] "GET /app HTTP/1.1" 200 5932
[12/Aug/2025 11:02:08] "GET /app/warehousing HTTP/1.1" 200 10517
[12/Aug/2025 11:02:08] "GET /api/auth/me/ HTTP/1.1" 200 181
[12/Aug/2025 11:02:08] "GET /api/warehousing/warehouses/?ordering=state,code&page_size=1000 HTTP/1.1" 200 2089
[12/Aug/2025 11:02:09] "GET /app/warehousing/w/BDVWH HTTP/1.1" 200 18336
[12/Aug/2025 11:02:09] "GET /api/auth/me/ HTTP/1.1" 200 181
[12/Aug/2025 11:02:09] "GET /api/warehousing/warehouses/1/kpis/ HTTP/1.1" 200 95
[12/Aug/2025 11:02:09] "GET /api/warehousing/warehouses/1/recent_activity/ HTTP/1.1" 200 4035
[12/Aug/2025 11:02:09] "GET /api/warehousing/warehouses/1/active_stock_summary/ HTTP/1.1" 200 201
[12/Aug/2025 11:02:09] "GET /api/warehousing/warehouses/1/physical_stock_summary/ HTTP/1.1" 200 35
[12/Aug/2025 11:02:12] "GET /app HTTP/1.1" 200 5932
/Users/dealshare/Documents/GitHub/kamna-erp/erp/cv_hub/models.py changed, reloading.
Performing system checks...

System check identified no issues (0 silenced).
August 12, 2025 - 11:00:44
Django version 5.2.4, using settings 'erp.settings'
Starting development server at http://127.0.0.1:8000/
Quit the server with CONTROL-C.

WARNING: This is a development server. Do not use it in a production setting. Use a production WSGI or ASGI server instead.
For more information on production servers see: https://docs.djangoproject.com/en/5.2/howto/deployment/
Watching for file changes with StatReloader
[12/Aug/2025 11:03:54] "GET /app/cv_hub/entries/ HTTP/1.1" 200 36884
[12/Aug/2025 11:03:54] "GET /api/cv_hub/states/ HTTP/1.1" 200 254
[12/Aug/2025 11:03:54] "GET /api/cv_hub/entries/?page=1 HTTP/1.1" 200 1216
[12/Aug/2025 11:03:59] "GET /app HTTP/1.1" 200 5932
[12/Aug/2025 11:04:23] "GET /app/cv_hub/entries/ HTTP/1.1" 200 36884
[12/Aug/2025 11:04:23] "GET /api/cv_hub/states/ HTTP/1.1" 200 254
[12/Aug/2025 11:04:23] "GET /api/cv_hub/entries/?page=1 HTTP/1.1" 200 1216
[12/Aug/2025 11:04:39] "GET /app/cv_hub/entries/2 HTTP/1.1" 200 36763
[12/Aug/2025 11:04:39] "GET /api/cv_hub/entries/2/ HTTP/1.1" 200 1606
[12/Aug/2025 11:04:46] "GET /app HTTP/1.1" 200 5932
[12/Aug/2025 11:04:49] "GET /app/cv_hub/entries/ HTTP/1.1" 200 36884
[12/Aug/2025 11:04:49] "GET /api/cv_hub/states/ HTTP/1.1" 200 254
[12/Aug/2025 11:04:49] "GET /api/cv_hub/entries/?page=1 HTTP/1.1" 200 1216
[12/Aug/2025 11:04:51] "GET /app/cv_hub/entries/2/edit HTTP/1.1" 200 43944
[12/Aug/2025 11:04:51] "GET /api/cv_hub/entries/2/ HTTP/1.1" 200 1606
/Users/dealshare/Documents/GitHub/kamna-erp/erp/cv_hub/api/views.py changed, reloading.
Performing system checks...

System check identified no issues (0 silenced).
August 12, 2025 - 11:02:26
Django version 5.2.4, using settings 'erp.settings'
Starting development server at http://127.0.0.1:8000/
Quit the server with CONTROL-C.

WARNING: This is a development server. Do not use it in a production setting. Use a production WSGI or ASGI server instead.
For more information on production servers see: https://docs.djangoproject.com/en/5.2/howto/deployment/
Watching for file changes with StatReloader
/Users/dealshare/Documents/GitHub/kamna-erp/erp/cv_hub/api/views.py changed, reloading.
Performing system checks...

System check identified no issues (0 silenced).
August 12, 2025 - 11:05:20
Django version 5.2.4, using settings 'erp.settings'
Starting development server at http://127.0.0.1:8000/
Quit the server with CONTROL-C.

WARNING: This is a development server. Do not use it in a production setting. Use a production WSGI or ASGI server instead.
For more information on production servers see: https://docs.djangoproject.com/en/5.2/howto/deployment/
Watching for file changes with StatReloader
[12/Aug/2025 11:08:31] "GET /app HTTP/1.1" 200 5932
[12/Aug/2025 11:08:39] "GET /app/cv_hub/entries/ HTTP/1.1" 200 36884
[12/Aug/2025 11:08:39] "GET /api/cv_hub/states/ HTTP/1.1" 200 254
[12/Aug/2025 11:08:39] "GET /api/cv_hub/entries/?page=1 HTTP/1.1" 200 1216
[12/Aug/2025 11:08:42] "GET /app/cv_hub HTTP/1.1" 200 16724
[12/Aug/2025 11:08:42] "GET /api/cv_hub/entries/ HTTP/1.1" 200 1216
[12/Aug/2025 11:08:42] "GET /api/cv_hub/entries/?is_customer=true&status=ACTIVE HTTP/1.1" 200 438
[12/Aug/2025 11:08:42] "GET /api/cv_hub/entries/?is_supplier=true&status=ACTIVE HTTP/1.1" 200 452
[12/Aug/2025 11:08:42] "GET /api/cv_hub/entries/?registrations__taxpayer_type=REGULAR HTTP/1.1" 200 1216
[12/Aug/2025 11:08:42] "GET /api/cv_hub/entries/?ordering=-updated_at&page_size=5 HTTP/1.1" 200 1216
[12/Aug/2025 11:08:45] "GET /app/cv_hub/entries/ HTTP/1.1" 200 36884
[12/Aug/2025 11:08:45] "GET /api/cv_hub/states/ HTTP/1.1" 200 254
[12/Aug/2025 11:08:45] "GET /api/cv_hub/entries/?page=1 HTTP/1.1" 200 1216
[12/Aug/2025 11:08:47] "GET /app/cv_hub/entries/2/edit HTTP/1.1" 200 43944
[12/Aug/2025 11:08:47] "GET /api/cv_hub/entries/2/ HTTP/1.1" 200 1606
[12/Aug/2025 11:08:51] "GET /app/cv_hub/entries/ HTTP/1.1" 200 36884
[12/Aug/2025 11:08:51] "GET /api/cv_hub/states/ HTTP/1.1" 200 254
[12/Aug/2025 11:08:51] "GET /api/cv_hub/entries/?page=1 HTTP/1.1" 200 1216
[12/Aug/2025 11:08:53] "GET /app/cv_hub/entries/2 HTTP/1.1" 200 38479
[12/Aug/2025 11:08:53] "GET /api/cv_hub/entries/2/ HTTP/1.1" 200 1606
[12/Aug/2025 11:09:03] "GET /api/cv_hub/entries/2/summary/ HTTP/1.1" 200 834
/Users/dealshare/Documents/GitHub/kamna-erp/erp/cv_hub/api/views.py changed, reloading.
Performing system checks...

System check identified no issues (0 silenced).
August 12, 2025 - 11:05:40
Django version 5.2.4, using settings 'erp.settings'
Starting development server at http://127.0.0.1:8000/
Quit the server with CONTROL-C.

WARNING: This is a development server. Do not use it in a production setting. Use a production WSGI or ASGI server instead.
For more information on production servers see: https://docs.djangoproject.com/en/5.2/howto/deployment/
Watching for file changes with StatReloader
/Users/dealshare/Documents/GitHub/kamna-erp/erp/cv_hub/api/views.py changed, reloading.
Performing system checks...

System check identified no issues (0 silenced).
August 12, 2025 - 11:09:25
Django version 5.2.4, using settings 'erp.settings'
Starting development server at http://127.0.0.1:8000/
Quit the server with CONTROL-C.

WARNING: This is a development server. Do not use it in a production setting. Use a production WSGI or ASGI server instead.
For more information on production servers see: https://docs.djangoproject.com/en/5.2/howto/deployment/
Watching for file changes with StatReloader
/Users/dealshare/Documents/GitHub/kamna-erp/erp/cv_hub/api/views.py changed, reloading.
Performing system checks...

System check identified no issues (0 silenced).
August 12, 2025 - 11:09:44
Django version 5.2.4, using settings 'erp.settings'
Starting development server at http://127.0.0.1:8000/
Quit the server with CONTROL-C.

WARNING: This is a development server. Do not use it in a production setting. Use a production WSGI or ASGI server instead.
For more information on production servers see: https://docs.djangoproject.com/en/5.2/howto/deployment/
Watching for file changes with StatReloader
/Users/dealshare/Documents/GitHub/kamna-erp/erp/cv_hub/api/views.py changed, reloading.
Performing system checks...

System check identified no issues (0 silenced).
August 12, 2025 - 11:12:50
Django version 5.2.4, using settings 'erp.settings'
Starting development server at http://127.0.0.1:8000/
Quit the server with CONTROL-C.

WARNING: This is a development server. Do not use it in a production setting. Use a production WSGI or ASGI server instead.
For more information on production servers see: https://docs.djangoproject.com/en/5.2/howto/deployment/
Watching for file changes with StatReloader
[12/Aug/2025 11:16:21] "GET /api/cv_hub/entries/ HTTP/1.1" 200 1216
[12/Aug/2025 11:16:46] "GET /api/cv_hub/entries/2/ HTTP/1.1" 200 1606
[12/Aug/2025 11:17:04] "PATCH /api/cv_hub/entries/2/ HTTP/1.1" 200 404
[12/Aug/2025 11:17:19] "GET /app/cv_hub/entries?id=b891f95e-b13a-48ed-b44b-feeedb6f5650&vscodeBrowserReqId=1755015439457 HTTP/1.1" 200 36884
[12/Aug/2025 11:17:29] "POST /api/cv_hub/contacts/ HTTP/1.1" 201 171
Internal Server Error: /api/cv_hub/addresses/
Traceback (most recent call last):
  File "/Users/dealshare/anaconda3/lib/python3.11/site-packages/rest_framework/serializers.py", line 991, in create
    instance = ModelClass._default_manager.create(**validated_data)
               ^^^^^^^^^^^^^^^^^^^^^^^^^^^^^^^^^^^^^^^^^^^^^^^^^^^^
  File "/Users/dealshare/anaconda3/lib/python3.11/site-packages/django/db/models/manager.py", line 87, in manager_method
    return getattr(self.get_queryset(), name)(*args, **kwargs)
           ^^^^^^^^^^^^^^^^^^^^^^^^^^^^^^^^^^^^^^^^^^^^^^^^^^^
  File "/Users/dealshare/anaconda3/lib/python3.11/site-packages/django/db/models/query.py", line 661, in create
    obj = self.model(**kwargs)
          ^^^^^^^^^^^^^^^^^^^^
  File "/Users/dealshare/anaconda3/lib/python3.11/site-packages/django/db/models/base.py", line 569, in __init__
    raise TypeError(
TypeError: CvHubAddress() got unexpected keyword arguments: 'created_by'

During handling of the above exception, another exception occurred:

Traceback (most recent call last):
  File "/Users/dealshare/anaconda3/lib/python3.11/site-packages/django/core/handlers/exception.py", line 55, in inner
    response = get_response(request)
               ^^^^^^^^^^^^^^^^^^^^^
  File "/Users/dealshare/anaconda3/lib/python3.11/site-packages/django/core/handlers/base.py", line 197, in _get_response
    response = wrapped_callback(request, *callback_args, **callback_kwargs)
               ^^^^^^^^^^^^^^^^^^^^^^^^^^^^^^^^^^^^^^^^^^^^^^^^^^^^^^^^^^^^
  File "/Users/dealshare/anaconda3/lib/python3.11/site-packages/django/views/decorators/csrf.py", line 65, in _view_wrapper
    return view_func(request, *args, **kwargs)
           ^^^^^^^^^^^^^^^^^^^^^^^^^^^^^^^^^^^
  File "/Users/dealshare/anaconda3/lib/python3.11/site-packages/rest_framework/viewsets.py", line 125, in view
    return self.dispatch(request, *args, **kwargs)
           ^^^^^^^^^^^^^^^^^^^^^^^^^^^^^^^^^^^^^^^
  File "/Users/dealshare/anaconda3/lib/python3.11/site-packages/rest_framework/views.py", line 515, in dispatch
    response = self.handle_exception(exc)
               ^^^^^^^^^^^^^^^^^^^^^^^^^^
  File "/Users/dealshare/anaconda3/lib/python3.11/site-packages/rest_framework/views.py", line 475, in handle_exception
    self.raise_uncaught_exception(exc)
  File "/Users/dealshare/anaconda3/lib/python3.11/site-packages/rest_framework/views.py", line 486, in raise_uncaught_exception
    raise exc
  File "/Users/dealshare/anaconda3/lib/python3.11/site-packages/rest_framework/views.py", line 512, in dispatch
    response = handler(request, *args, **kwargs)
               ^^^^^^^^^^^^^^^^^^^^^^^^^^^^^^^^^
  File "/Users/dealshare/anaconda3/lib/python3.11/site-packages/rest_framework/mixins.py", line 19, in create
    self.perform_create(serializer)
  File "/Users/dealshare/Documents/GitHub/kamna-erp/erp/cv_hub/api/views.py", line 160, in perform_create
    serializer.save(created_by=self.request.user if self.request.user.is_authenticated else None)
  File "/Users/dealshare/anaconda3/lib/python3.11/site-packages/rest_framework/serializers.py", line 210, in save
    self.instance = self.create(validated_data)
                    ^^^^^^^^^^^^^^^^^^^^^^^^^^^
  File "/Users/dealshare/anaconda3/lib/python3.11/site-packages/rest_framework/serializers.py", line 1010, in create
    raise TypeError(msg)
TypeError: Got a `TypeError` when calling `CvHubAddress.objects.create()`. This may be because you have a writable field on the serializer class that is not a valid argument to `CvHubAddress.objects.create()`. You may need to make the field read-only, or override the CvHubAddressSerializer.create() method to handle this correctly.
Original exception was:
 Traceback (most recent call last):
  File "/Users/dealshare/anaconda3/lib/python3.11/site-packages/rest_framework/serializers.py", line 991, in create
    instance = ModelClass._default_manager.create(**validated_data)
               ^^^^^^^^^^^^^^^^^^^^^^^^^^^^^^^^^^^^^^^^^^^^^^^^^^^^
  File "/Users/dealshare/anaconda3/lib/python3.11/site-packages/django/db/models/manager.py", line 87, in manager_method
    return getattr(self.get_queryset(), name)(*args, **kwargs)
           ^^^^^^^^^^^^^^^^^^^^^^^^^^^^^^^^^^^^^^^^^^^^^^^^^^^
  File "/Users/dealshare/anaconda3/lib/python3.11/site-packages/django/db/models/query.py", line 661, in create
    obj = self.model(**kwargs)
          ^^^^^^^^^^^^^^^^^^^^
  File "/Users/dealshare/anaconda3/lib/python3.11/site-packages/django/db/models/base.py", line 569, in __init__
    raise TypeError(
TypeError: CvHubAddress() got unexpected keyword arguments: 'created_by'

[12/Aug/2025 11:17:39] "POST /api/cv_hub/addresses/ HTTP/1.1" 500 154641
Internal Server Error: /api/cv_hub/addresses/
Traceback (most recent call last):
  File "/Users/dealshare/anaconda3/lib/python3.11/site-packages/rest_framework/serializers.py", line 991, in create
    instance = ModelClass._default_manager.create(**validated_data)
               ^^^^^^^^^^^^^^^^^^^^^^^^^^^^^^^^^^^^^^^^^^^^^^^^^^^^
  File "/Users/dealshare/anaconda3/lib/python3.11/site-packages/django/db/models/manager.py", line 87, in manager_method
    return getattr(self.get_queryset(), name)(*args, **kwargs)
           ^^^^^^^^^^^^^^^^^^^^^^^^^^^^^^^^^^^^^^^^^^^^^^^^^^^
  File "/Users/dealshare/anaconda3/lib/python3.11/site-packages/django/db/models/query.py", line 661, in create
    obj = self.model(**kwargs)
          ^^^^^^^^^^^^^^^^^^^^
  File "/Users/dealshare/anaconda3/lib/python3.11/site-packages/django/db/models/base.py", line 569, in __init__
    raise TypeError(
TypeError: CvHubAddress() got unexpected keyword arguments: 'created_by'

During handling of the above exception, another exception occurred:

Traceback (most recent call last):
  File "/Users/dealshare/anaconda3/lib/python3.11/site-packages/django/core/handlers/exception.py", line 55, in inner
    response = get_response(request)
               ^^^^^^^^^^^^^^^^^^^^^
  File "/Users/dealshare/anaconda3/lib/python3.11/site-packages/django/core/handlers/base.py", line 197, in _get_response
    response = wrapped_callback(request, *callback_args, **callback_kwargs)
               ^^^^^^^^^^^^^^^^^^^^^^^^^^^^^^^^^^^^^^^^^^^^^^^^^^^^^^^^^^^^
  File "/Users/dealshare/anaconda3/lib/python3.11/site-packages/django/views/decorators/csrf.py", line 65, in _view_wrapper
    return view_func(request, *args, **kwargs)
           ^^^^^^^^^^^^^^^^^^^^^^^^^^^^^^^^^^^
  File "/Users/dealshare/anaconda3/lib/python3.11/site-packages/rest_framework/viewsets.py", line 125, in view
    return self.dispatch(request, *args, **kwargs)
           ^^^^^^^^^^^^^^^^^^^^^^^^^^^^^^^^^^^^^^^
  File "/Users/dealshare/anaconda3/lib/python3.11/site-packages/rest_framework/views.py", line 515, in dispatch
    response = self.handle_exception(exc)
               ^^^^^^^^^^^^^^^^^^^^^^^^^^
  File "/Users/dealshare/anaconda3/lib/python3.11/site-packages/rest_framework/views.py", line 475, in handle_exception
    self.raise_uncaught_exception(exc)
  File "/Users/dealshare/anaconda3/lib/python3.11/site-packages/rest_framework/views.py", line 486, in raise_uncaught_exception
    raise exc
  File "/Users/dealshare/anaconda3/lib/python3.11/site-packages/rest_framework/views.py", line 512, in dispatch
    response = handler(request, *args, **kwargs)
               ^^^^^^^^^^^^^^^^^^^^^^^^^^^^^^^^^
  File "/Users/dealshare/anaconda3/lib/python3.11/site-packages/rest_framework/mixins.py", line 19, in create
    self.perform_create(serializer)
  File "/Users/dealshare/Documents/GitHub/kamna-erp/erp/cv_hub/api/views.py", line 160, in perform_create
    serializer.save(created_by=self.request.user if self.request.user.is_authenticated else None)
  File "/Users/dealshare/anaconda3/lib/python3.11/site-packages/rest_framework/serializers.py", line 210, in save
    self.instance = self.create(validated_data)
                    ^^^^^^^^^^^^^^^^^^^^^^^^^^^
  File "/Users/dealshare/anaconda3/lib/python3.11/site-packages/rest_framework/serializers.py", line 1010, in create
    raise TypeError(msg)
TypeError: Got a `TypeError` when calling `CvHubAddress.objects.create()`. This may be because you have a writable field on the serializer class that is not a valid argument to `CvHubAddress.objects.create()`. You may need to make the field read-only, or override the CvHubAddressSerializer.create() method to handle this correctly.
Original exception was:
 Traceback (most recent call last):
  File "/Users/dealshare/anaconda3/lib/python3.11/site-packages/rest_framework/serializers.py", line 991, in create
    instance = ModelClass._default_manager.create(**validated_data)
               ^^^^^^^^^^^^^^^^^^^^^^^^^^^^^^^^^^^^^^^^^^^^^^^^^^^^
  File "/Users/dealshare/anaconda3/lib/python3.11/site-packages/django/db/models/manager.py", line 87, in manager_method
    return getattr(self.get_queryset(), name)(*args, **kwargs)
           ^^^^^^^^^^^^^^^^^^^^^^^^^^^^^^^^^^^^^^^^^^^^^^^^^^^
  File "/Users/dealshare/anaconda3/lib/python3.11/site-packages/django/db/models/query.py", line 661, in create
    obj = self.model(**kwargs)
          ^^^^^^^^^^^^^^^^^^^^
  File "/Users/dealshare/anaconda3/lib/python3.11/site-packages/django/db/models/base.py", line 569, in __init__
    raise TypeError(
TypeError: CvHubAddress() got unexpected keyword arguments: 'created_by'

[12/Aug/2025 11:17:57] "POST /api/cv_hub/addresses/ HTTP/1.1" 500 154641
[12/Aug/2025 11:18:56] "GET /api/cv_hub/entries/ HTTP/1.1" 200 1220
[12/Aug/2025 11:18:56] "GET /api/cv_hub/states/ HTTP/1.1" 200 254
[12/Aug/2025 11:18:56] "GET /api/cv_hub/cities/ HTTP/1.1" 200 462
/Users/dealshare/anaconda3/lib/python3.11/site-packages/rest_framework/pagination.py:207: UnorderedObjectListWarning: Pagination may yield inconsistent results with an unordered object_list: <class 'cv_hub.models.CvHubGSTRegistration'> QuerySet.
  paginator = self.django_paginator_class(queryset, page_size)
[12/Aug/2025 11:18:56] "GET /api/cv_hub/registrations/ HTTP/1.1" 200 1459
/Users/dealshare/anaconda3/lib/python3.11/site-packages/rest_framework/pagination.py:207: UnorderedObjectListWarning: Pagination may yield inconsistent results with an unordered object_list: <class 'cv_hub.models.CvHubAddress'> QuerySet.
  paginator = self.django_paginator_class(queryset, page_size)
[12/Aug/2025 11:18:56] "GET /api/cv_hub/addresses/ HTTP/1.1" 200 590
/Users/dealshare/anaconda3/lib/python3.11/site-packages/rest_framework/pagination.py:207: UnorderedObjectListWarning: Pagination may yield inconsistent results with an unordered object_list: <class 'cv_hub.models.CvHubContact'> QuerySet.
  paginator = self.django_paginator_class(queryset, page_size)
[12/Aug/2025 11:18:56] "GET /api/cv_hub/contacts/ HTTP/1.1" 200 600
[12/Aug/2025 11:18:56] "GET /app/cv_hub HTTP/1.1" 200 16724
[12/Aug/2025 11:18:56] "GET /app/cv_hub/entries HTTP/1.1" 200 36884
[12/Aug/2025 11:18:56] "GET /app/cv_hub/entries/new HTTP/1.1" 200 36884
[12/Aug/2025 11:18:56] "GET /api/cv_hub/entries/?for_sales=true HTTP/1.1" 200 815
[12/Aug/2025 11:18:56] "GET /api/cv_hub/states/ HTTP/1.1" 200 254
[12/Aug/2025 11:20:10] "GET /api/cv_hub/entries/2/ HTTP/1.1" 200 1782
[12/Aug/2025 11:20:10] "GET /api/cv_hub/contacts/ HTTP/1.1" 200 600
[12/Aug/2025 11:20:10] "GET /api/cv_hub/entries/2/ HTTP/1.1" 200 1782
[12/Aug/2025 11:20:11] "GET /api/cv_hub/entries/2/history/ HTTP/1.1" 200 1047
[12/Aug/2025 11:21:55] "GET /app/cv_hub/entries/2 HTTP/1.1" 200 41396
[12/Aug/2025 11:21:55] "GET /api/cv_hub/entries/2/ HTTP/1.1" 200 1782
[12/Aug/2025 11:21:55] "GET /api/cv_hub/entries/2/history/ HTTP/1.1" 200 1047
[12/Aug/2025 11:21:58] "GET /app/cv_hub/entries/ HTTP/1.1" 200 36884
[12/Aug/2025 11:21:58] "GET /api/cv_hub/states/ HTTP/1.1" 200 254
[12/Aug/2025 11:21:58] "GET /api/cv_hub/entries/?page=1 HTTP/1.1" 200 1220
[12/Aug/2025 11:22:00] "GET /app/cv_hub/entries/8 HTTP/1.1" 200 41396
[12/Aug/2025 11:22:00] "GET /api/cv_hub/entries/8/ HTTP/1.1" 200 961
[12/Aug/2025 11:22:00] "GET /api/cv_hub/entries/8/history/ HTTP/1.1" 200 784
[12/Aug/2025 11:22:05] "GET /app/cv_hub/entries/8/edit HTTP/1.1" 200 43944
[12/Aug/2025 11:22:05] "GET /api/cv_hub/entries/8/ HTTP/1.1" 200 961
[12/Aug/2025 11:22:12] "GET /api/cv_hub/states/ HTTP/1.1" 200 254
[12/Aug/2025 11:22:20] "GET /api/cv_hub/cities/?state=1 HTTP/1.1" 200 194
Internal Server Error: /api/cv_hub/addresses/
Traceback (most recent call last):
  File "/Users/dealshare/anaconda3/lib/python3.11/site-packages/rest_framework/serializers.py", line 991, in create
    instance = ModelClass._default_manager.create(**validated_data)
               ^^^^^^^^^^^^^^^^^^^^^^^^^^^^^^^^^^^^^^^^^^^^^^^^^^^^
  File "/Users/dealshare/anaconda3/lib/python3.11/site-packages/django/db/models/manager.py", line 87, in manager_method
    return getattr(self.get_queryset(), name)(*args, **kwargs)
           ^^^^^^^^^^^^^^^^^^^^^^^^^^^^^^^^^^^^^^^^^^^^^^^^^^^
  File "/Users/dealshare/anaconda3/lib/python3.11/site-packages/django/db/models/query.py", line 661, in create
    obj = self.model(**kwargs)
          ^^^^^^^^^^^^^^^^^^^^
  File "/Users/dealshare/anaconda3/lib/python3.11/site-packages/django/db/models/base.py", line 569, in __init__
    raise TypeError(
TypeError: CvHubAddress() got unexpected keyword arguments: 'created_by'

During handling of the above exception, another exception occurred:

Traceback (most recent call last):
  File "/Users/dealshare/anaconda3/lib/python3.11/site-packages/django/core/handlers/exception.py", line 55, in inner
    response = get_response(request)
               ^^^^^^^^^^^^^^^^^^^^^
  File "/Users/dealshare/anaconda3/lib/python3.11/site-packages/django/core/handlers/base.py", line 197, in _get_response
    response = wrapped_callback(request, *callback_args, **callback_kwargs)
               ^^^^^^^^^^^^^^^^^^^^^^^^^^^^^^^^^^^^^^^^^^^^^^^^^^^^^^^^^^^^
  File "/Users/dealshare/anaconda3/lib/python3.11/site-packages/django/views/decorators/csrf.py", line 65, in _view_wrapper
    return view_func(request, *args, **kwargs)
           ^^^^^^^^^^^^^^^^^^^^^^^^^^^^^^^^^^^
  File "/Users/dealshare/anaconda3/lib/python3.11/site-packages/rest_framework/viewsets.py", line 125, in view
    return self.dispatch(request, *args, **kwargs)
           ^^^^^^^^^^^^^^^^^^^^^^^^^^^^^^^^^^^^^^^
  File "/Users/dealshare/anaconda3/lib/python3.11/site-packages/rest_framework/views.py", line 515, in dispatch
    response = self.handle_exception(exc)
               ^^^^^^^^^^^^^^^^^^^^^^^^^^
  File "/Users/dealshare/anaconda3/lib/python3.11/site-packages/rest_framework/views.py", line 475, in handle_exception
    self.raise_uncaught_exception(exc)
  File "/Users/dealshare/anaconda3/lib/python3.11/site-packages/rest_framework/views.py", line 486, in raise_uncaught_exception
    raise exc
  File "/Users/dealshare/anaconda3/lib/python3.11/site-packages/rest_framework/views.py", line 512, in dispatch
    response = handler(request, *args, **kwargs)
               ^^^^^^^^^^^^^^^^^^^^^^^^^^^^^^^^^
  File "/Users/dealshare/anaconda3/lib/python3.11/site-packages/rest_framework/mixins.py", line 19, in create
    self.perform_create(serializer)
  File "/Users/dealshare/Documents/GitHub/kamna-erp/erp/cv_hub/api/views.py", line 160, in perform_create
    serializer.save(created_by=self.request.user if self.request.user.is_authenticated else None)
  File "/Users/dealshare/anaconda3/lib/python3.11/site-packages/rest_framework/serializers.py", line 210, in save
    self.instance = self.create(validated_data)
                    ^^^^^^^^^^^^^^^^^^^^^^^^^^^
  File "/Users/dealshare/anaconda3/lib/python3.11/site-packages/rest_framework/serializers.py", line 1010, in create
    raise TypeError(msg)
TypeError: Got a `TypeError` when calling `CvHubAddress.objects.create()`. This may be because you have a writable field on the serializer class that is not a valid argument to `CvHubAddress.objects.create()`. You may need to make the field read-only, or override the CvHubAddressSerializer.create() method to handle this correctly.
Original exception was:
 Traceback (most recent call last):
  File "/Users/dealshare/anaconda3/lib/python3.11/site-packages/rest_framework/serializers.py", line 991, in create
    instance = ModelClass._default_manager.create(**validated_data)
               ^^^^^^^^^^^^^^^^^^^^^^^^^^^^^^^^^^^^^^^^^^^^^^^^^^^^
  File "/Users/dealshare/anaconda3/lib/python3.11/site-packages/django/db/models/manager.py", line 87, in manager_method
    return getattr(self.get_queryset(), name)(*args, **kwargs)
           ^^^^^^^^^^^^^^^^^^^^^^^^^^^^^^^^^^^^^^^^^^^^^^^^^^^
  File "/Users/dealshare/anaconda3/lib/python3.11/site-packages/django/db/models/query.py", line 661, in create
    obj = self.model(**kwargs)
          ^^^^^^^^^^^^^^^^^^^^
  File "/Users/dealshare/anaconda3/lib/python3.11/site-packages/django/db/models/base.py", line 569, in __init__
    raise TypeError(
TypeError: CvHubAddress() got unexpected keyword arguments: 'created_by'

[12/Aug/2025 11:22:26] "POST /api/cv_hub/addresses/ HTTP/1.1" 500 158666
Internal Server Error: /api/cv_hub/addresses/
Traceback (most recent call last):
  File "/Users/dealshare/anaconda3/lib/python3.11/site-packages/rest_framework/serializers.py", line 991, in create
    instance = ModelClass._default_manager.create(**validated_data)
               ^^^^^^^^^^^^^^^^^^^^^^^^^^^^^^^^^^^^^^^^^^^^^^^^^^^^
  File "/Users/dealshare/anaconda3/lib/python3.11/site-packages/django/db/models/manager.py", line 87, in manager_method
    return getattr(self.get_queryset(), name)(*args, **kwargs)
           ^^^^^^^^^^^^^^^^^^^^^^^^^^^^^^^^^^^^^^^^^^^^^^^^^^^
  File "/Users/dealshare/anaconda3/lib/python3.11/site-packages/django/db/models/query.py", line 661, in create
    obj = self.model(**kwargs)
          ^^^^^^^^^^^^^^^^^^^^
  File "/Users/dealshare/anaconda3/lib/python3.11/site-packages/django/db/models/base.py", line 569, in __init__
    raise TypeError(
TypeError: CvHubAddress() got unexpected keyword arguments: 'created_by'

During handling of the above exception, another exception occurred:

Traceback (most recent call last):
  File "/Users/dealshare/anaconda3/lib/python3.11/site-packages/django/core/handlers/exception.py", line 55, in inner
    response = get_response(request)
               ^^^^^^^^^^^^^^^^^^^^^
  File "/Users/dealshare/anaconda3/lib/python3.11/site-packages/django/core/handlers/base.py", line 197, in _get_response
    response = wrapped_callback(request, *callback_args, **callback_kwargs)
               ^^^^^^^^^^^^^^^^^^^^^^^^^^^^^^^^^^^^^^^^^^^^^^^^^^^^^^^^^^^^
  File "/Users/dealshare/anaconda3/lib/python3.11/site-packages/django/views/decorators/csrf.py", line 65, in _view_wrapper
    return view_func(request, *args, **kwargs)
           ^^^^^^^^^^^^^^^^^^^^^^^^^^^^^^^^^^^
  File "/Users/dealshare/anaconda3/lib/python3.11/site-packages/rest_framework/viewsets.py", line 125, in view
    return self.dispatch(request, *args, **kwargs)
           ^^^^^^^^^^^^^^^^^^^^^^^^^^^^^^^^^^^^^^^
  File "/Users/dealshare/anaconda3/lib/python3.11/site-packages/rest_framework/views.py", line 515, in dispatch
    response = self.handle_exception(exc)
               ^^^^^^^^^^^^^^^^^^^^^^^^^^
  File "/Users/dealshare/anaconda3/lib/python3.11/site-packages/rest_framework/views.py", line 475, in handle_exception
    self.raise_uncaught_exception(exc)
  File "/Users/dealshare/anaconda3/lib/python3.11/site-packages/rest_framework/views.py", line 486, in raise_uncaught_exception
    raise exc
  File "/Users/dealshare/anaconda3/lib/python3.11/site-packages/rest_framework/views.py", line 512, in dispatch
    response = handler(request, *args, **kwargs)
               ^^^^^^^^^^^^^^^^^^^^^^^^^^^^^^^^^
  File "/Users/dealshare/anaconda3/lib/python3.11/site-packages/rest_framework/mixins.py", line 19, in create
    self.perform_create(serializer)
  File "/Users/dealshare/Documents/GitHub/kamna-erp/erp/cv_hub/api/views.py", line 160, in perform_create
    serializer.save(created_by=self.request.user if self.request.user.is_authenticated else None)
  File "/Users/dealshare/anaconda3/lib/python3.11/site-packages/rest_framework/serializers.py", line 210, in save
    self.instance = self.create(validated_data)
                    ^^^^^^^^^^^^^^^^^^^^^^^^^^^
  File "/Users/dealshare/anaconda3/lib/python3.11/site-packages/rest_framework/serializers.py", line 1010, in create
    raise TypeError(msg)
TypeError: Got a `TypeError` when calling `CvHubAddress.objects.create()`. This may be because you have a writable field on the serializer class that is not a valid argument to `CvHubAddress.objects.create()`. You may need to make the field read-only, or override the CvHubAddressSerializer.create() method to handle this correctly.
Original exception was:
 Traceback (most recent call last):
  File "/Users/dealshare/anaconda3/lib/python3.11/site-packages/rest_framework/serializers.py", line 991, in create
    instance = ModelClass._default_manager.create(**validated_data)
               ^^^^^^^^^^^^^^^^^^^^^^^^^^^^^^^^^^^^^^^^^^^^^^^^^^^^
  File "/Users/dealshare/anaconda3/lib/python3.11/site-packages/django/db/models/manager.py", line 87, in manager_method
    return getattr(self.get_queryset(), name)(*args, **kwargs)
           ^^^^^^^^^^^^^^^^^^^^^^^^^^^^^^^^^^^^^^^^^^^^^^^^^^^
  File "/Users/dealshare/anaconda3/lib/python3.11/site-packages/django/db/models/query.py", line 661, in create
    obj = self.model(**kwargs)
          ^^^^^^^^^^^^^^^^^^^^
  File "/Users/dealshare/anaconda3/lib/python3.11/site-packages/django/db/models/base.py", line 569, in __init__
    raise TypeError(
TypeError: CvHubAddress() got unexpected keyword arguments: 'created_by'

[12/Aug/2025 11:22:28] "POST /api/cv_hub/addresses/ HTTP/1.1" 500 158666
Internal Server Error: /api/cv_hub/addresses/
Traceback (most recent call last):
  File "/Users/dealshare/anaconda3/lib/python3.11/site-packages/rest_framework/serializers.py", line 991, in create
    instance = ModelClass._default_manager.create(**validated_data)
               ^^^^^^^^^^^^^^^^^^^^^^^^^^^^^^^^^^^^^^^^^^^^^^^^^^^^
  File "/Users/dealshare/anaconda3/lib/python3.11/site-packages/django/db/models/manager.py", line 87, in manager_method
    return getattr(self.get_queryset(), name)(*args, **kwargs)
           ^^^^^^^^^^^^^^^^^^^^^^^^^^^^^^^^^^^^^^^^^^^^^^^^^^^
  File "/Users/dealshare/anaconda3/lib/python3.11/site-packages/django/db/models/query.py", line 661, in create
    obj = self.model(**kwargs)
          ^^^^^^^^^^^^^^^^^^^^
  File "/Users/dealshare/anaconda3/lib/python3.11/site-packages/django/db/models/base.py", line 569, in __init__
    raise TypeError(
TypeError: CvHubAddress() got unexpected keyword arguments: 'created_by'

During handling of the above exception, another exception occurred:

Traceback (most recent call last):
  File "/Users/dealshare/anaconda3/lib/python3.11/site-packages/django/core/handlers/exception.py", line 55, in inner
    response = get_response(request)
               ^^^^^^^^^^^^^^^^^^^^^
  File "/Users/dealshare/anaconda3/lib/python3.11/site-packages/django/core/handlers/base.py", line 197, in _get_response
    response = wrapped_callback(request, *callback_args, **callback_kwargs)
               ^^^^^^^^^^^^^^^^^^^^^^^^^^^^^^^^^^^^^^^^^^^^^^^^^^^^^^^^^^^^
  File "/Users/dealshare/anaconda3/lib/python3.11/site-packages/django/views/decorators/csrf.py", line 65, in _view_wrapper
    return view_func(request, *args, **kwargs)
           ^^^^^^^^^^^^^^^^^^^^^^^^^^^^^^^^^^^
  File "/Users/dealshare/anaconda3/lib/python3.11/site-packages/rest_framework/viewsets.py", line 125, in view
    return self.dispatch(request, *args, **kwargs)
           ^^^^^^^^^^^^^^^^^^^^^^^^^^^^^^^^^^^^^^^
  File "/Users/dealshare/anaconda3/lib/python3.11/site-packages/rest_framework/views.py", line 515, in dispatch
    response = self.handle_exception(exc)
               ^^^^^^^^^^^^^^^^^^^^^^^^^^
  File "/Users/dealshare/anaconda3/lib/python3.11/site-packages/rest_framework/views.py", line 475, in handle_exception
    self.raise_uncaught_exception(exc)
  File "/Users/dealshare/anaconda3/lib/python3.11/site-packages/rest_framework/views.py", line 486, in raise_uncaught_exception
    raise exc
  File "/Users/dealshare/anaconda3/lib/python3.11/site-packages/rest_framework/views.py", line 512, in dispatch
    response = handler(request, *args, **kwargs)
               ^^^^^^^^^^^^^^^^^^^^^^^^^^^^^^^^^
  File "/Users/dealshare/anaconda3/lib/python3.11/site-packages/rest_framework/mixins.py", line 19, in create
    self.perform_create(serializer)
  File "/Users/dealshare/Documents/GitHub/kamna-erp/erp/cv_hub/api/views.py", line 160, in perform_create
    serializer.save(created_by=self.request.user if self.request.user.is_authenticated else None)
  File "/Users/dealshare/anaconda3/lib/python3.11/site-packages/rest_framework/serializers.py", line 210, in save
    self.instance = self.create(validated_data)
                    ^^^^^^^^^^^^^^^^^^^^^^^^^^^
  File "/Users/dealshare/anaconda3/lib/python3.11/site-packages/rest_framework/serializers.py", line 1010, in create
    raise TypeError(msg)
TypeError: Got a `TypeError` when calling `CvHubAddress.objects.create()`. This may be because you have a writable field on the serializer class that is not a valid argument to `CvHubAddress.objects.create()`. You may need to make the field read-only, or override the CvHubAddressSerializer.create() method to handle this correctly.
Original exception was:
 Traceback (most recent call last):
  File "/Users/dealshare/anaconda3/lib/python3.11/site-packages/rest_framework/serializers.py", line 991, in create
    instance = ModelClass._default_manager.create(**validated_data)
               ^^^^^^^^^^^^^^^^^^^^^^^^^^^^^^^^^^^^^^^^^^^^^^^^^^^^
  File "/Users/dealshare/anaconda3/lib/python3.11/site-packages/django/db/models/manager.py", line 87, in manager_method
    return getattr(self.get_queryset(), name)(*args, **kwargs)
           ^^^^^^^^^^^^^^^^^^^^^^^^^^^^^^^^^^^^^^^^^^^^^^^^^^^
  File "/Users/dealshare/anaconda3/lib/python3.11/site-packages/django/db/models/query.py", line 661, in create
    obj = self.model(**kwargs)
          ^^^^^^^^^^^^^^^^^^^^
  File "/Users/dealshare/anaconda3/lib/python3.11/site-packages/django/db/models/base.py", line 569, in __init__
    raise TypeError(
TypeError: CvHubAddress() got unexpected keyword arguments: 'created_by'

[12/Aug/2025 11:22:32] "POST /api/cv_hub/addresses/ HTTP/1.1" 500 158676
Bad Request: /api/cv_hub/addresses/
[12/Aug/2025 11:22:37] "POST /api/cv_hub/addresses/ HTTP/1.1" 400 44
Bad Request: /api/cv_hub/addresses/
[12/Aug/2025 11:22:39] "POST /api/cv_hub/addresses/ HTTP/1.1" 400 44
Bad Request: /api/cv_hub/addresses/
[12/Aug/2025 11:22:45] "POST /api/cv_hub/addresses/ HTTP/1.1" 400 44
Bad Request: /api/cv_hub/entries/8/
[12/Aug/2025 11:23:16] "PATCH /api/cv_hub/entries/8/ HTTP/1.1" 400 34
[12/Aug/2025 11:23:18] "GET /app/cv_hub/entries/ HTTP/1.1" 200 36884
[12/Aug/2025 11:23:18] "GET /api/cv_hub/states/ HTTP/1.1" 200 254
[12/Aug/2025 11:23:18] "GET /api/cv_hub/entries/?page=1 HTTP/1.1" 200 1220
[12/Aug/2025 11:23:21] "GET /app/cv_hub/entries/8 HTTP/1.1" 200 41396
[12/Aug/2025 11:23:21] "GET /api/cv_hub/entries/8/ HTTP/1.1" 200 961
[12/Aug/2025 11:23:21] "GET /api/cv_hub/entries/8/history/ HTTP/1.1" 200 784
[12/Aug/2025 11:23:47] "GET /api/cv_hub/entries/8/summary/ HTTP/1.1" 200 292
[12/Aug/2025 11:23:57] "GET /app/cv_hub/entries/8 HTTP/1.1" 200 41396
[12/Aug/2025 11:23:57] "GET /api/cv_hub/entries/8/ HTTP/1.1" 200 961
[12/Aug/2025 11:23:57] "GET /api/cv_hub/entries/8/history/ HTTP/1.1" 200 784
[12/Aug/2025 11:24:07] "POST /api/cv_hub/registrations/ HTTP/1.1" 201 344
[12/Aug/2025 11:24:07] "GET /app/cv_hub/entries/8 HTTP/1.1" 200 41396
[12/Aug/2025 11:24:07] "GET /api/cv_hub/entries/8/ HTTP/1.1" 200 1307
[12/Aug/2025 11:24:07] "GET /api/cv_hub/entries/8/history/ HTTP/1.1" 200 912
[12/Aug/2025 11:24:16] "GET /app/cv_hub/entries/8/edit HTTP/1.1" 200 43944
[12/Aug/2025 11:24:16] "GET /api/cv_hub/entries/8/ HTTP/1.1" 200 1307
[12/Aug/2025 11:26:07] "GET /app/cv_hub/entries/8/edit HTTP/1.1" 200 43944
[12/Aug/2025 11:26:07] "GET /api/cv_hub/entries/8/ HTTP/1.1" 200 1307
[12/Aug/2025 11:26:08] "GET /app/cv_hub/entries/8/edit HTTP/1.1" 200 43944
[12/Aug/2025 11:26:08] "GET /api/cv_hub/entries/8/ HTTP/1.1" 200 1307
[12/Aug/2025 11:26:12] "GET /app/cv_hub/entries/ HTTP/1.1" 200 36884
[12/Aug/2025 11:26:12] "GET /api/cv_hub/states/ HTTP/1.1" 200 254
[12/Aug/2025 11:26:12] "GET /api/cv_hub/entries/?page=1 HTTP/1.1" 200 1220
[12/Aug/2025 11:26:14] "GET /app/cv_hub/entries/8 HTTP/1.1" 200 41396
[12/Aug/2025 11:26:14] "GET /api/cv_hub/entries/8/ HTTP/1.1" 200 1307
[12/Aug/2025 11:26:14] "GET /api/cv_hub/entries/8/history/ HTTP/1.1" 200 912
[12/Aug/2025 11:26:17] "GET /app/cv_hub/entries/8 HTTP/1.1" 200 41396
[12/Aug/2025 11:26:18] "GET /api/cv_hub/entries/8/ HTTP/1.1" 200 1307
[12/Aug/2025 11:26:18] "GET /api/cv_hub/entries/8/history/ HTTP/1.1" 200 912
[12/Aug/2025 11:26:30] "GET /app/cv_hub/entries/ HTTP/1.1" 200 36884
[12/Aug/2025 11:26:30] "GET /api/cv_hub/states/ HTTP/1.1" 200 254
[12/Aug/2025 11:26:30] "GET /api/cv_hub/entries/?page=1 HTTP/1.1" 200 1220
[12/Aug/2025 11:26:32] "GET /app/cv_hub/entries/8/edit HTTP/1.1" 200 43944
[12/Aug/2025 11:26:32] "GET /api/cv_hub/entries/8/ HTTP/1.1" 200 1307
[12/Aug/2025 11:27:14] "GET /app/cv_hub/entries/ HTTP/1.1" 200 36884
[12/Aug/2025 11:27:15] "GET /api/cv_hub/states/ HTTP/1.1" 200 254
[12/Aug/2025 11:27:15] "GET /api/cv_hub/entries/?page=1 HTTP/1.1" 200 1220
[12/Aug/2025 11:27:16] "GET /app/cv_hub/entries/2 HTTP/1.1" 200 41396
[12/Aug/2025 11:27:16] "GET /api/cv_hub/entries/2/ HTTP/1.1" 200 1782
[12/Aug/2025 11:27:16] "GET /api/cv_hub/entries/2/history/ HTTP/1.1" 200 1047
[12/Aug/2025 11:27:41] "GET /app/cv_hub HTTP/1.1" 200 16724
[12/Aug/2025 11:27:41] "GET /api/cv_hub/entries/?is_customer=true&status=ACTIVE HTTP/1.1" 200 438
[12/Aug/2025 11:27:41] "GET /api/cv_hub/entries/?is_supplier=true&status=ACTIVE HTTP/1.1" 200 456
[12/Aug/2025 11:27:41] "GET /api/cv_hub/entries/ HTTP/1.1" 200 1220
[12/Aug/2025 11:27:41] "GET /api/cv_hub/entries/?registrations__taxpayer_type=REGULAR HTTP/1.1" 200 1607
[12/Aug/2025 11:27:41] "GET /api/cv_hub/entries/?ordering=-updated_at&page_size=5 HTTP/1.1" 200 1220
[12/Aug/2025 11:27:43] "GET /app/cv_hub/entries/ HTTP/1.1" 200 36884
[12/Aug/2025 11:27:43] "GET /api/cv_hub/states/ HTTP/1.1" 200 254
[12/Aug/2025 11:27:43] "GET /api/cv_hub/entries/?page=1 HTTP/1.1" 200 1220
/Users/dealshare/Documents/GitHub/kamna-erp/erp/cv_hub/models.py changed, reloading.
Performing system checks...

System check identified no issues (0 silenced).
August 12, 2025 - 11:15:06
Django version 5.2.4, using settings 'erp.settings'
Starting development server at http://127.0.0.1:8000/
Quit the server with CONTROL-C.

WARNING: This is a development server. Do not use it in a production setting. Use a production WSGI or ASGI server instead.
For more information on production servers see: https://docs.djangoproject.com/en/5.2/howto/deployment/
Watching for file changes with StatReloader
/Users/dealshare/Documents/GitHub/kamna-erp/erp/cv_hub/signals.py changed, reloading.
Performing system checks...

System check identified no issues (0 silenced).
August 12, 2025 - 11:29:59
Django version 5.2.4, using settings 'erp.settings'
Starting development server at http://127.0.0.1:8000/
Quit the server with CONTROL-C.

WARNING: This is a development server. Do not use it in a production setting. Use a production WSGI or ASGI server instead.
For more information on production servers see: https://docs.djangoproject.com/en/5.2/howto/deployment/
Watching for file changes with StatReloader
/Users/dealshare/Documents/GitHub/kamna-erp/erp/cv_hub/models.py changed, reloading.
Performing system checks...

System check identified no issues (0 silenced).
August 12, 2025 - 11:30:24
Django version 5.2.4, using settings 'erp.settings'
Starting development server at http://127.0.0.1:8000/
Quit the server with CONTROL-C.

WARNING: This is a development server. Do not use it in a production setting. Use a production WSGI or ASGI server instead.
For more information on production servers see: https://docs.djangoproject.com/en/5.2/howto/deployment/
Watching for file changes with StatReloader
[12/Aug/2025 11:43:52] "GET /app HTTP/1.1" 200 5932
[12/Aug/2025 11:44:40] "GET /app HTTP/1.1" 200 5932
[12/Aug/2025 11:44:41] "GET /app/cv_hub/entries/ HTTP/1.1" 200 36884
[12/Aug/2025 11:44:41] "GET /api/cv_hub/states/ HTTP/1.1" 200 254
[12/Aug/2025 11:44:41] "GET /api/cv_hub/entries/?page=1 HTTP/1.1" 200 1220
[12/Aug/2025 11:44:43] "GET /app/cv_hub/entries/8/edit HTTP/1.1" 200 53388
[12/Aug/2025 11:44:43] "GET /api/cv_hub/entries/8/ HTTP/1.1" 200 1136
Bad Request: /api/cv_hub/registrations/
[12/Aug/2025 11:44:54] "POST /api/cv_hub/registrations/ HTTP/1.1" 400 127
[12/Aug/2025 11:44:58] "GET /app/cv_hub/entries/8/edit HTTP/1.1" 200 53388
[12/Aug/2025 11:44:58] "GET /api/cv_hub/entries/8/ HTTP/1.1" 200 1136
Bad Request: /api/cv_hub/entries/8/
[12/Aug/2025 11:45:17] "PATCH /api/cv_hub/entries/8/ HTTP/1.1" 400 34
[12/Aug/2025 11:45:20] "GET /app/cv_hub/entries/8/edit HTTP/1.1" 200 53388
[12/Aug/2025 11:45:20] "GET /api/cv_hub/entries/8/ HTTP/1.1" 200 1136
[12/Aug/2025 11:45:32] "DELETE /api/cv_hub/contacts/19/ HTTP/1.1" 204 0
[12/Aug/2025 11:45:32] "GET /api/cv_hub/entries/8/ HTTP/1.1" 200 962
[12/Aug/2025 11:45:34] "GET /app/cv_hub/entries/ HTTP/1.1" 200 36884
[12/Aug/2025 11:45:34] "GET /api/cv_hub/states/ HTTP/1.1" 200 254
[12/Aug/2025 11:45:34] "GET /api/cv_hub/entries/?page=1 HTTP/1.1" 200 1220
[12/Aug/2025 11:45:36] "GET /app/cv_hub/entries/8 HTTP/1.1" 200 41396
[12/Aug/2025 11:45:36] "GET /api/cv_hub/entries/8/ HTTP/1.1" 200 962
[12/Aug/2025 11:45:36] "GET /api/cv_hub/entries/8/history/ HTTP/1.1" 200 784
[12/Aug/2025 11:45:44] "GET /app/cv_hub/entries/8/edit HTTP/1.1" 200 53388
[12/Aug/2025 11:45:44] "GET /api/cv_hub/entries/8/ HTTP/1.1" 200 962
[12/Aug/2025 11:45:45] "GET /api/cv_hub/entries/8/history/ HTTP/1.1" 200 784
[12/Aug/2025 11:45:55] "GET /app/cv_hub HTTP/1.1" 200 16724
[12/Aug/2025 11:45:56] "GET /api/cv_hub/entries/ HTTP/1.1" 200 1220
[12/Aug/2025 11:45:56] "GET /api/cv_hub/entries/?is_customer=true&status=ACTIVE HTTP/1.1" 200 438
[12/Aug/2025 11:45:56] "GET /api/cv_hub/entries/?is_supplier=true&status=ACTIVE HTTP/1.1" 200 456
[12/Aug/2025 11:45:56] "GET /api/cv_hub/entries/?registrations__taxpayer_type=REGULAR HTTP/1.1" 200 1220
[12/Aug/2025 11:45:56] "GET /api/cv_hub/entries/?ordering=-updated_at&page_size=5 HTTP/1.1" 200 1220
[12/Aug/2025 11:47:01] "GET /app/cv_hub/entries/ HTTP/1.1" 200 36884
[12/Aug/2025 11:47:01] "GET /api/cv_hub/states/ HTTP/1.1" 200 254
[12/Aug/2025 11:47:01] "GET /api/cv_hub/entries/?page=1 HTTP/1.1" 200 1220
[12/Aug/2025 11:47:07] "GET /app/cv_hub/entries/8 HTTP/1.1" 200 41396
[12/Aug/2025 11:47:07] "GET /api/cv_hub/entries/8/ HTTP/1.1" 200 962
[12/Aug/2025 11:47:07] "GET /api/cv_hub/entries/8/history/ HTTP/1.1" 200 784
[12/Aug/2025 11:47:26] "GET /app/cv_hub/entries/8/edit HTTP/1.1" 200 53388
[12/Aug/2025 11:47:26] "GET /api/cv_hub/entries/8/ HTTP/1.1" 200 962
Bad Request: /api/cv_hub/entries/8/
[12/Aug/2025 11:47:37] "PATCH /api/cv_hub/entries/8/ HTTP/1.1" 400 34
Bad Request: /api/cv_hub/entries/8/
[12/Aug/2025 11:48:27] "PATCH /api/cv_hub/entries/8/ HTTP/1.1" 400 34
[12/Aug/2025 11:48:31] "GET /app/cv_hub/entries/ HTTP/1.1" 200 36884
[12/Aug/2025 11:48:31] "GET /api/cv_hub/states/ HTTP/1.1" 200 254
[12/Aug/2025 11:48:31] "GET /api/cv_hub/entries/?page=1 HTTP/1.1" 200 1220
[12/Aug/2025 11:48:32] "GET /app/cv_hub/entries/ HTTP/1.1" 200 36884
[12/Aug/2025 11:48:32] "GET /api/cv_hub/states/ HTTP/1.1" 200 254
[12/Aug/2025 11:48:32] "GET /api/cv_hub/entries/?page=1 HTTP/1.1" 200 1220
[12/Aug/2025 11:48:32] "GET /app/cv_hub/entries/ HTTP/1.1" 200 36884
[12/Aug/2025 11:48:32] "GET /api/cv_hub/states/ HTTP/1.1" 200 254
[12/Aug/2025 11:48:32] "GET /api/cv_hub/entries/?page=1 HTTP/1.1" 200 1220
[12/Aug/2025 11:48:32] "GET /app/cv_hub/entries/ HTTP/1.1" 200 36884
[12/Aug/2025 11:48:32] "GET /api/cv_hub/states/ HTTP/1.1" 200 254
[12/Aug/2025 11:48:32] "GET /api/cv_hub/entries/?page=1 HTTP/1.1" 200 1220
[12/Aug/2025 11:58:18] "GET /app/cv_hub/entries/8/edit HTTP/1.1" 200 53691
[12/Aug/2025 11:58:18] "GET /api/cv_hub/entries/8/ HTTP/1.1" 200 962
[12/Aug/2025 11:58:26] "PATCH /api/cv_hub/entries/8/ HTTP/1.1" 200 419
[12/Aug/2025 11:58:26] "GET /app/cv_hub/entries/8 HTTP/1.1" 200 41396
[12/Aug/2025 11:58:26] "GET /api/cv_hub/entries/8/ HTTP/1.1" 200 995
[12/Aug/2025 11:58:26] "GET /api/cv_hub/entries/8/history/ HTTP/1.1" 200 940
[12/Aug/2025 12:03:08] "GET /app/cv_hub/entries/8/edit HTTP/1.1" 200 53691
[12/Aug/2025 12:03:08] "GET /api/cv_hub/entries/8/ HTTP/1.1" 200 995
Bad Request: /api/cv_hub/registrations/
[12/Aug/2025 12:03:17] "POST /api/cv_hub/registrations/ HTTP/1.1" 400 127
[12/Aug/2025 12:04:04] "GET /api/cv_hub/states/ HTTP/1.1" 200 254
[12/Aug/2025 12:04:20] "GET /api/cv_hub/cities/?state=1 HTTP/1.1" 200 194
Internal Server Error: /api/cv_hub/addresses/
Traceback (most recent call last):
  File "/Users/dealshare/anaconda3/lib/python3.11/site-packages/rest_framework/serializers.py", line 991, in create
    instance = ModelClass._default_manager.create(**validated_data)
               ^^^^^^^^^^^^^^^^^^^^^^^^^^^^^^^^^^^^^^^^^^^^^^^^^^^^
  File "/Users/dealshare/anaconda3/lib/python3.11/site-packages/django/db/models/manager.py", line 87, in manager_method
    return getattr(self.get_queryset(), name)(*args, **kwargs)
           ^^^^^^^^^^^^^^^^^^^^^^^^^^^^^^^^^^^^^^^^^^^^^^^^^^^
  File "/Users/dealshare/anaconda3/lib/python3.11/site-packages/django/db/models/query.py", line 661, in create
    obj = self.model(**kwargs)
          ^^^^^^^^^^^^^^^^^^^^
  File "/Users/dealshare/anaconda3/lib/python3.11/site-packages/django/db/models/base.py", line 569, in __init__
    raise TypeError(
TypeError: CvHubAddress() got unexpected keyword arguments: 'created_by'

During handling of the above exception, another exception occurred:

Traceback (most recent call last):
  File "/Users/dealshare/anaconda3/lib/python3.11/site-packages/django/core/handlers/exception.py", line 55, in inner
    response = get_response(request)
               ^^^^^^^^^^^^^^^^^^^^^
  File "/Users/dealshare/anaconda3/lib/python3.11/site-packages/django/core/handlers/base.py", line 197, in _get_response
    response = wrapped_callback(request, *callback_args, **callback_kwargs)
               ^^^^^^^^^^^^^^^^^^^^^^^^^^^^^^^^^^^^^^^^^^^^^^^^^^^^^^^^^^^^
  File "/Users/dealshare/anaconda3/lib/python3.11/site-packages/django/views/decorators/csrf.py", line 65, in _view_wrapper
    return view_func(request, *args, **kwargs)
           ^^^^^^^^^^^^^^^^^^^^^^^^^^^^^^^^^^^
  File "/Users/dealshare/anaconda3/lib/python3.11/site-packages/rest_framework/viewsets.py", line 125, in view
    return self.dispatch(request, *args, **kwargs)
           ^^^^^^^^^^^^^^^^^^^^^^^^^^^^^^^^^^^^^^^
  File "/Users/dealshare/anaconda3/lib/python3.11/site-packages/rest_framework/views.py", line 515, in dispatch
    response = self.handle_exception(exc)
               ^^^^^^^^^^^^^^^^^^^^^^^^^^
  File "/Users/dealshare/anaconda3/lib/python3.11/site-packages/rest_framework/views.py", line 475, in handle_exception
    self.raise_uncaught_exception(exc)
  File "/Users/dealshare/anaconda3/lib/python3.11/site-packages/rest_framework/views.py", line 486, in raise_uncaught_exception
    raise exc
  File "/Users/dealshare/anaconda3/lib/python3.11/site-packages/rest_framework/views.py", line 512, in dispatch
    response = handler(request, *args, **kwargs)
               ^^^^^^^^^^^^^^^^^^^^^^^^^^^^^^^^^
  File "/Users/dealshare/anaconda3/lib/python3.11/site-packages/rest_framework/mixins.py", line 19, in create
    self.perform_create(serializer)
  File "/Users/dealshare/Documents/GitHub/kamna-erp/erp/cv_hub/api/views.py", line 160, in perform_create
    serializer.save(created_by=self.request.user if self.request.user.is_authenticated else None)
  File "/Users/dealshare/anaconda3/lib/python3.11/site-packages/rest_framework/serializers.py", line 210, in save
    self.instance = self.create(validated_data)
                    ^^^^^^^^^^^^^^^^^^^^^^^^^^^
  File "/Users/dealshare/anaconda3/lib/python3.11/site-packages/rest_framework/serializers.py", line 1010, in create
    raise TypeError(msg)
TypeError: Got a `TypeError` when calling `CvHubAddress.objects.create()`. This may be because you have a writable field on the serializer class that is not a valid argument to `CvHubAddress.objects.create()`. You may need to make the field read-only, or override the CvHubAddressSerializer.create() method to handle this correctly.
Original exception was:
 Traceback (most recent call last):
  File "/Users/dealshare/anaconda3/lib/python3.11/site-packages/rest_framework/serializers.py", line 991, in create
    instance = ModelClass._default_manager.create(**validated_data)
               ^^^^^^^^^^^^^^^^^^^^^^^^^^^^^^^^^^^^^^^^^^^^^^^^^^^^
  File "/Users/dealshare/anaconda3/lib/python3.11/site-packages/django/db/models/manager.py", line 87, in manager_method
    return getattr(self.get_queryset(), name)(*args, **kwargs)
           ^^^^^^^^^^^^^^^^^^^^^^^^^^^^^^^^^^^^^^^^^^^^^^^^^^^
  File "/Users/dealshare/anaconda3/lib/python3.11/site-packages/django/db/models/query.py", line 661, in create
    obj = self.model(**kwargs)
          ^^^^^^^^^^^^^^^^^^^^
  File "/Users/dealshare/anaconda3/lib/python3.11/site-packages/django/db/models/base.py", line 569, in __init__
    raise TypeError(
TypeError: CvHubAddress() got unexpected keyword arguments: 'created_by'

[12/Aug/2025 12:04:26] "POST /api/cv_hub/addresses/ HTTP/1.1" 500 158666
[12/Aug/2025 12:04:29] "GET /api/cv_hub/states/ HTTP/1.1" 200 254
[12/Aug/2025 12:04:40] "GET /app/cv_hub/entries/ HTTP/1.1" 200 36884
[12/Aug/2025 12:04:40] "GET /api/cv_hub/states/ HTTP/1.1" 200 254
[12/Aug/2025 12:04:40] "GET /api/cv_hub/entries/?page=1 HTTP/1.1" 200 1253
[12/Aug/2025 12:04:41] "GET /app/cv_hub/entries/ HTTP/1.1" 200 36884
[12/Aug/2025 12:04:41] "GET /api/cv_hub/states/ HTTP/1.1" 200 254
[12/Aug/2025 12:04:41] "GET /api/cv_hub/entries/?page=1 HTTP/1.1" 200 1253
[12/Aug/2025 12:04:41] "GET /app/cv_hub/entries/ HTTP/1.1" 200 36884
[12/Aug/2025 12:04:41] "GET /api/cv_hub/states/ HTTP/1.1" 200 254
[12/Aug/2025 12:04:41] "GET /api/cv_hub/entries/?page=1 HTTP/1.1" 200 1253
[12/Aug/2025 12:04:41] "GET /app/cv_hub/entries/ HTTP/1.1" 200 36884
[12/Aug/2025 12:04:41] "GET /api/cv_hub/states/ HTTP/1.1" 200 254
[12/Aug/2025 12:04:41] "GET /api/cv_hub/entries/?page=1 HTTP/1.1" 200 1253
[12/Aug/2025 12:04:48] "GET /app/cv_hub/entries/8 HTTP/1.1" 200 41396
[12/Aug/2025 12:04:48] "GET /api/cv_hub/entries/8/ HTTP/1.1" 200 995
[12/Aug/2025 12:04:48] "GET /api/cv_hub/entries/8/history/ HTTP/1.1" 200 940
[12/Aug/2025 12:04:57] "GET /app/cv_hub/entries/8 HTTP/1.1" 200 41396
[12/Aug/2025 12:04:57] "GET /api/cv_hub/entries/8/ HTTP/1.1" 200 995
[12/Aug/2025 12:04:57] "GET /api/cv_hub/entries/8/history/ HTTP/1.1" 200 940
[12/Aug/2025 12:04:59] "GET /api/cv_hub/states/ HTTP/1.1" 200 254
[12/Aug/2025 12:05:02] "GET /app/cv_hub/entries/8 HTTP/1.1" 200 41396
[12/Aug/2025 12:05:02] "GET /api/cv_hub/entries/8/ HTTP/1.1" 200 995
[12/Aug/2025 12:05:02] "GET /api/cv_hub/entries/8/history/ HTTP/1.1" 200 940
[12/Aug/2025 12:05:18] "GET /app/cv_hub/entries/8 HTTP/1.1" 200 41396
[12/Aug/2025 12:05:18] "GET /api/cv_hub/entries/8/ HTTP/1.1" 200 995
[12/Aug/2025 12:05:18] "GET /api/cv_hub/entries/8/history/ HTTP/1.1" 200 940
[12/Aug/2025 12:05:18] "GET /app/cv_hub/entries/8 HTTP/1.1" 200 41396
[12/Aug/2025 12:05:18] "GET /api/cv_hub/entries/8/ HTTP/1.1" 200 995
[12/Aug/2025 12:05:18] "GET /api/cv_hub/entries/8/history/ HTTP/1.1" 200 940
[12/Aug/2025 12:05:18] "GET /app/cv_hub/entries/8 HTTP/1.1" 200 41396
[12/Aug/2025 12:05:18] "GET /api/cv_hub/entries/8/ HTTP/1.1" 200 995
[12/Aug/2025 12:05:18] "GET /api/cv_hub/entries/8/history/ HTTP/1.1" 200 940
/Users/dealshare/Documents/GitHub/kamna-erp/erp/cv_hub/api/serializers.py changed, reloading.
Performing system checks...

System check identified no issues (0 silenced).
August 12, 2025 - 11:32:16
Django version 5.2.4, using settings 'erp.settings'
Starting development server at http://127.0.0.1:8000/
Quit the server with CONTROL-C.

WARNING: This is a development server. Do not use it in a production setting. Use a production WSGI or ASGI server instead.
For more information on production servers see: https://docs.djangoproject.com/en/5.2/howto/deployment/
Watching for file changes with StatReloader
/Users/dealshare/Documents/GitHub/kamna-erp/erp/cv_hub/api/serializers.py changed, reloading.
Performing system checks...

System check identified no issues (0 silenced).
August 12, 2025 - 12:10:37
Django version 5.2.4, using settings 'erp.settings'
Starting development server at http://127.0.0.1:8000/
Quit the server with CONTROL-C.

WARNING: This is a development server. Do not use it in a production setting. Use a production WSGI or ASGI server instead.
For more information on production servers see: https://docs.djangoproject.com/en/5.2/howto/deployment/
Watching for file changes with StatReloader
/Users/dealshare/Documents/GitHub/kamna-erp/erp/cv_hub/models.py changed, reloading.
Performing system checks...

System check identified no issues (0 silenced).
August 12, 2025 - 12:11:37
Django version 5.2.4, using settings 'erp.settings'
Starting development server at http://127.0.0.1:8000/
Quit the server with CONTROL-C.

WARNING: This is a development server. Do not use it in a production setting. Use a production WSGI or ASGI server instead.
For more information on production servers see: https://docs.djangoproject.com/en/5.2/howto/deployment/
Watching for file changes with StatReloader
/Users/dealshare/Documents/GitHub/kamna-erp/erp/cv_hub/models.py changed, reloading.
Performing system checks...

System check identified no issues (0 silenced).
August 12, 2025 - 12:12:14
Django version 5.2.4, using settings 'erp.settings'
Starting development server at http://127.0.0.1:8000/
Quit the server with CONTROL-C.

WARNING: This is a development server. Do not use it in a production setting. Use a production WSGI or ASGI server instead.
For more information on production servers see: https://docs.djangoproject.com/en/5.2/howto/deployment/
Watching for file changes with StatReloader
[12/Aug/2025 12:16:34] "GET /app/cv_hub/entries/8 HTTP/1.1" 200 43464
[12/Aug/2025 12:16:34] "GET /api/cv_hub/entries/8/ HTTP/1.1" 200 650
[12/Aug/2025 12:16:34] "GET /api/cv_hub/entries/8/history/ HTTP/1.1" 200 812
[12/Aug/2025 12:16:47] "POST /api/cv_hub/registrations/ HTTP/1.1" 201 344
[12/Aug/2025 12:16:47] "GET /app/cv_hub/entries/8 HTTP/1.1" 200 43464
[12/Aug/2025 12:16:47] "GET /api/cv_hub/entries/8/ HTTP/1.1" 200 994
[12/Aug/2025 12:16:47] "GET /api/cv_hub/entries/8/history/ HTTP/1.1" 200 940
Bad Request: /api/cv_hub/registrations/
[12/Aug/2025 12:16:57] "POST /api/cv_hub/registrations/ HTTP/1.1" 400 80
[12/Aug/2025 12:17:44] "GET /app HTTP/1.1" 200 5932
[12/Aug/2025 12:17:45] "GET /app/cv_hub/entries/ HTTP/1.1" 200 36884
[12/Aug/2025 12:17:45] "GET /api/cv_hub/states/ HTTP/1.1" 200 254
[12/Aug/2025 12:17:45] "GET /api/cv_hub/entries/?page=1 HTTP/1.1" 200 3405
[12/Aug/2025 12:17:51] "GET /app/cv_hub/entries/22 HTTP/1.1" 200 43464
[12/Aug/2025 12:17:51] "GET /api/cv_hub/entries/22/ HTTP/1.1" 200 741
[12/Aug/2025 12:17:51] "GET /api/cv_hub/entries/22/history/ HTTP/1.1" 200 246
Bad Request: /api/cv_hub/registrations/
[12/Aug/2025 12:17:59] "POST /api/cv_hub/registrations/ HTTP/1.1" 400 80
[12/Aug/2025 12:18:17] "GET /app HTTP/1.1" 200 5932
[12/Aug/2025 12:18:19] "GET /app/cv_hub/entries/ HTTP/1.1" 200 36884
[12/Aug/2025 12:18:19] "GET /api/cv_hub/states/ HTTP/1.1" 200 254
[12/Aug/2025 12:18:19] "GET /api/cv_hub/entries/?page=1 HTTP/1.1" 200 3405
[12/Aug/2025 12:18:31] "GET /app/cv_hub/entries/22 HTTP/1.1" 200 43464
[12/Aug/2025 12:18:31] "GET /api/cv_hub/entries/22/ HTTP/1.1" 200 741
[12/Aug/2025 12:18:31] "GET /api/cv_hub/entries/22/history/ HTTP/1.1" 200 246
[12/Aug/2025 12:18:35] "GET /app/cv_hub/entries/22/edit HTTP/1.1" 200 54555
[12/Aug/2025 12:18:35] "GET /api/cv_hub/entries/22/ HTTP/1.1" 200 741
[12/Aug/2025 12:19:12] "PATCH /api/cv_hub/entries/22/ HTTP/1.1" 200 365
[12/Aug/2025 12:19:12] "GET /app/cv_hub/entries/22 HTTP/1.1" 200 43464
[12/Aug/2025 12:19:12] "GET /api/cv_hub/entries/22/ HTTP/1.1" 200 741
[12/Aug/2025 12:19:12] "GET /api/cv_hub/entries/22/history/ HTTP/1.1" 200 363
[12/Aug/2025 12:19:14] "GET /app/cv_hub/entries/22/edit HTTP/1.1" 200 54555
[12/Aug/2025 12:19:14] "GET /api/cv_hub/entries/22/ HTTP/1.1" 200 741
[12/Aug/2025 12:19:27] "POST /api/cv_hub/registrations/ HTTP/1.1" 201 327
[12/Aug/2025 12:19:27] "GET /api/cv_hub/entries/22/ HTTP/1.1" 200 1069
[12/Aug/2025 12:19:29] "PATCH /api/cv_hub/entries/22/ HTTP/1.1" 200 365
[12/Aug/2025 12:19:29] "GET /app/cv_hub/entries/22 HTTP/1.1" 200 43464
[12/Aug/2025 12:19:29] "GET /api/cv_hub/entries/22/ HTTP/1.1" 200 1069
[12/Aug/2025 12:19:29] "GET /api/cv_hub/entries/22/history/ HTTP/1.1" 200 608
[12/Aug/2025 12:19:32] "GET /app/cv_hub/entries/22/edit HTTP/1.1" 200 54555
[12/Aug/2025 12:19:32] "GET /api/cv_hub/entries/22/ HTTP/1.1" 200 1069
[12/Aug/2025 12:19:36] "GET /api/cv_hub/entries/22/history/ HTTP/1.1" 200 608
[12/Aug/2025 12:19:42] "GET /api/cv_hub/entries/22/history/ HTTP/1.1" 200 608
[12/Aug/2025 12:19:46] "GET /api/cv_hub/states/ HTTP/1.1" 200 254
[12/Aug/2025 12:19:56] "GET /api/cv_hub/cities/?state=4 HTTP/1.1" 200 126
Internal Server Error: /api/cv_hub/addresses/
Traceback (most recent call last):
  File "/Users/dealshare/anaconda3/lib/python3.11/site-packages/rest_framework/serializers.py", line 991, in create
    instance = ModelClass._default_manager.create(**validated_data)
               ^^^^^^^^^^^^^^^^^^^^^^^^^^^^^^^^^^^^^^^^^^^^^^^^^^^^
  File "/Users/dealshare/anaconda3/lib/python3.11/site-packages/django/db/models/manager.py", line 87, in manager_method
    return getattr(self.get_queryset(), name)(*args, **kwargs)
           ^^^^^^^^^^^^^^^^^^^^^^^^^^^^^^^^^^^^^^^^^^^^^^^^^^^
  File "/Users/dealshare/anaconda3/lib/python3.11/site-packages/django/db/models/query.py", line 661, in create
    obj = self.model(**kwargs)
          ^^^^^^^^^^^^^^^^^^^^
  File "/Users/dealshare/anaconda3/lib/python3.11/site-packages/django/db/models/base.py", line 569, in __init__
    raise TypeError(
TypeError: CvHubAddress() got unexpected keyword arguments: 'created_by'

During handling of the above exception, another exception occurred:

Traceback (most recent call last):
  File "/Users/dealshare/anaconda3/lib/python3.11/site-packages/django/core/handlers/exception.py", line 55, in inner
    response = get_response(request)
               ^^^^^^^^^^^^^^^^^^^^^
  File "/Users/dealshare/anaconda3/lib/python3.11/site-packages/django/core/handlers/base.py", line 197, in _get_response
    response = wrapped_callback(request, *callback_args, **callback_kwargs)
               ^^^^^^^^^^^^^^^^^^^^^^^^^^^^^^^^^^^^^^^^^^^^^^^^^^^^^^^^^^^^
  File "/Users/dealshare/anaconda3/lib/python3.11/site-packages/django/views/decorators/csrf.py", line 65, in _view_wrapper
    return view_func(request, *args, **kwargs)
           ^^^^^^^^^^^^^^^^^^^^^^^^^^^^^^^^^^^
  File "/Users/dealshare/anaconda3/lib/python3.11/site-packages/rest_framework/viewsets.py", line 125, in view
    return self.dispatch(request, *args, **kwargs)
           ^^^^^^^^^^^^^^^^^^^^^^^^^^^^^^^^^^^^^^^
  File "/Users/dealshare/anaconda3/lib/python3.11/site-packages/rest_framework/views.py", line 515, in dispatch
    response = self.handle_exception(exc)
               ^^^^^^^^^^^^^^^^^^^^^^^^^^
  File "/Users/dealshare/anaconda3/lib/python3.11/site-packages/rest_framework/views.py", line 475, in handle_exception
    self.raise_uncaught_exception(exc)
  File "/Users/dealshare/anaconda3/lib/python3.11/site-packages/rest_framework/views.py", line 486, in raise_uncaught_exception
    raise exc
  File "/Users/dealshare/anaconda3/lib/python3.11/site-packages/rest_framework/views.py", line 512, in dispatch
    response = handler(request, *args, **kwargs)
               ^^^^^^^^^^^^^^^^^^^^^^^^^^^^^^^^^
  File "/Users/dealshare/anaconda3/lib/python3.11/site-packages/rest_framework/mixins.py", line 19, in create
    self.perform_create(serializer)
  File "/Users/dealshare/Documents/GitHub/kamna-erp/erp/cv_hub/api/views.py", line 160, in perform_create
    serializer.save(created_by=self.request.user if self.request.user.is_authenticated else None)
  File "/Users/dealshare/anaconda3/lib/python3.11/site-packages/rest_framework/serializers.py", line 210, in save
    self.instance = self.create(validated_data)
                    ^^^^^^^^^^^^^^^^^^^^^^^^^^^
  File "/Users/dealshare/anaconda3/lib/python3.11/site-packages/rest_framework/serializers.py", line 1010, in create
    raise TypeError(msg)
TypeError: Got a `TypeError` when calling `CvHubAddress.objects.create()`. This may be because you have a writable field on the serializer class that is not a valid argument to `CvHubAddress.objects.create()`. You may need to make the field read-only, or override the CvHubAddressSerializer.create() method to handle this correctly.
Original exception was:
 Traceback (most recent call last):
  File "/Users/dealshare/anaconda3/lib/python3.11/site-packages/rest_framework/serializers.py", line 991, in create
    instance = ModelClass._default_manager.create(**validated_data)
               ^^^^^^^^^^^^^^^^^^^^^^^^^^^^^^^^^^^^^^^^^^^^^^^^^^^^
  File "/Users/dealshare/anaconda3/lib/python3.11/site-packages/django/db/models/manager.py", line 87, in manager_method
    return getattr(self.get_queryset(), name)(*args, **kwargs)
           ^^^^^^^^^^^^^^^^^^^^^^^^^^^^^^^^^^^^^^^^^^^^^^^^^^^
  File "/Users/dealshare/anaconda3/lib/python3.11/site-packages/django/db/models/query.py", line 661, in create
    obj = self.model(**kwargs)
          ^^^^^^^^^^^^^^^^^^^^
  File "/Users/dealshare/anaconda3/lib/python3.11/site-packages/django/db/models/base.py", line 569, in __init__
    raise TypeError(
TypeError: CvHubAddress() got unexpected keyword arguments: 'created_by'

[12/Aug/2025 12:20:01] "POST /api/cv_hub/addresses/ HTTP/1.1" 500 158620
[12/Aug/2025 12:20:30] "GET /api/cv_hub/entries/22/history/ HTTP/1.1" 200 608
[12/Aug/2025 12:20:36] "GET /app/cv_hub/entries/22 HTTP/1.1" 200 43464
[12/Aug/2025 12:20:36] "GET /api/cv_hub/entries/22/ HTTP/1.1" 200 1069
[12/Aug/2025 12:20:36] "GET /api/cv_hub/entries/22/history/ HTTP/1.1" 200 608
[12/Aug/2025 12:20:56] "GET /app/cv_hub/entries/ HTTP/1.1" 200 36884
[12/Aug/2025 12:20:56] "GET /api/cv_hub/states/ HTTP/1.1" 200 254
[12/Aug/2025 12:20:56] "GET /api/cv_hub/entries/?page=1 HTTP/1.1" 200 3405
[12/Aug/2025 12:20:58] "GET /app/cv_hub/entries/8 HTTP/1.1" 200 43464
[12/Aug/2025 12:20:58] "GET /api/cv_hub/entries/8/ HTTP/1.1" 200 994
[12/Aug/2025 12:20:58] "GET /api/cv_hub/entries/8/history/ HTTP/1.1" 200 940
[12/Aug/2025 12:21:01] "GET /app/cv_hub/entries/ HTTP/1.1" 200 36884
[12/Aug/2025 12:21:01] "GET /api/cv_hub/states/ HTTP/1.1" 200 254
[12/Aug/2025 12:21:01] "GET /api/cv_hub/entries/?page=1 HTTP/1.1" 200 3405
[12/Aug/2025 12:21:52] "POST /api/cv_hub/entries/ HTTP/1.1" 201 381
[12/Aug/2025 12:21:52] "POST /api/cv_hub/registrations/ HTTP/1.1" 201 337
Bad Request: /api/cv_hub/contacts/
[12/Aug/2025 12:21:52] "POST /api/cv_hub/contacts/ HTTP/1.1" 400 98
[12/Aug/2025 12:21:52] "GET /api/cv_hub/entries/?page=1 HTTP/1.1" 200 3823
[12/Aug/2025 12:21:55] "GET /api/cv_hub/entries/?page=2 HTTP/1.1" 200 828
[12/Aug/2025 12:21:58] "GET /api/cv_hub/entries/?page=1 HTTP/1.1" 200 3823
[12/Aug/2025 12:22:00] "GET /app/cv_hub/entries/28 HTTP/1.1" 200 43464
[12/Aug/2025 12:22:00] "GET /api/cv_hub/entries/28/ HTTP/1.1" 200 766
[12/Aug/2025 12:22:00] "GET /api/cv_hub/entries/28/history/ HTTP/1.1" 200 246
[12/Aug/2025 12:22:10] "GET /app/cv_hub/entries/28/edit HTTP/1.1" 200 55794
[12/Aug/2025 12:22:10] "GET /api/cv_hub/entries/28/ HTTP/1.1" 200 766
[12/Aug/2025 12:22:18] "GET /api/cv_hub/entries/28/history/ HTTP/1.1" 200 246
[12/Aug/2025 12:22:21] "GET /app/cv_hub/entries/ HTTP/1.1" 200 36884
[12/Aug/2025 12:22:21] "GET /api/cv_hub/states/ HTTP/1.1" 200 254
[12/Aug/2025 12:22:21] "GET /api/cv_hub/entries/?page=1 HTTP/1.1" 200 3823
[12/Aug/2025 12:22:22] "GET /app HTTP/1.1" 200 5932
[12/Aug/2025 12:22:24] "GET /app/cv_hub/entries/ HTTP/1.1" 200 36884
[12/Aug/2025 12:22:24] "GET /api/cv_hub/states/ HTTP/1.1" 200 254
[12/Aug/2025 12:22:24] "GET /api/cv_hub/entries/?page=1 HTTP/1.1" 200 3823
[12/Aug/2025 12:25:59] "GET /app/cv_hub/entries/28/edit HTTP/1.1" 200 57004
[12/Aug/2025 12:25:59] "GET /api/cv_hub/entries/28/ HTTP/1.1" 200 766
[12/Aug/2025 12:26:01] "GET /api/cv_hub/states/ HTTP/1.1" 200 254
[12/Aug/2025 12:26:10] "GET /api/cv_hub/cities/?state=2 HTTP/1.1" 200 123
Internal Server Error: /api/cv_hub/addresses/
Traceback (most recent call last):
  File "/Users/dealshare/anaconda3/lib/python3.11/site-packages/rest_framework/serializers.py", line 991, in create
    instance = ModelClass._default_manager.create(**validated_data)
               ^^^^^^^^^^^^^^^^^^^^^^^^^^^^^^^^^^^^^^^^^^^^^^^^^^^^
  File "/Users/dealshare/anaconda3/lib/python3.11/site-packages/django/db/models/manager.py", line 87, in manager_method
    return getattr(self.get_queryset(), name)(*args, **kwargs)
           ^^^^^^^^^^^^^^^^^^^^^^^^^^^^^^^^^^^^^^^^^^^^^^^^^^^
  File "/Users/dealshare/anaconda3/lib/python3.11/site-packages/django/db/models/query.py", line 661, in create
    obj = self.model(**kwargs)
          ^^^^^^^^^^^^^^^^^^^^
  File "/Users/dealshare/anaconda3/lib/python3.11/site-packages/django/db/models/base.py", line 569, in __init__
    raise TypeError(
TypeError: CvHubAddress() got unexpected keyword arguments: 'created_by'

During handling of the above exception, another exception occurred:

Traceback (most recent call last):
  File "/Users/dealshare/anaconda3/lib/python3.11/site-packages/django/core/handlers/exception.py", line 55, in inner
    response = get_response(request)
               ^^^^^^^^^^^^^^^^^^^^^
  File "/Users/dealshare/anaconda3/lib/python3.11/site-packages/django/core/handlers/base.py", line 197, in _get_response
    response = wrapped_callback(request, *callback_args, **callback_kwargs)
               ^^^^^^^^^^^^^^^^^^^^^^^^^^^^^^^^^^^^^^^^^^^^^^^^^^^^^^^^^^^^
  File "/Users/dealshare/anaconda3/lib/python3.11/site-packages/django/views/decorators/csrf.py", line 65, in _view_wrapper
    return view_func(request, *args, **kwargs)
           ^^^^^^^^^^^^^^^^^^^^^^^^^^^^^^^^^^^
  File "/Users/dealshare/anaconda3/lib/python3.11/site-packages/rest_framework/viewsets.py", line 125, in view
    return self.dispatch(request, *args, **kwargs)
           ^^^^^^^^^^^^^^^^^^^^^^^^^^^^^^^^^^^^^^^
  File "/Users/dealshare/anaconda3/lib/python3.11/site-packages/rest_framework/views.py", line 515, in dispatch
    response = self.handle_exception(exc)
               ^^^^^^^^^^^^^^^^^^^^^^^^^^
  File "/Users/dealshare/anaconda3/lib/python3.11/site-packages/rest_framework/views.py", line 475, in handle_exception
    self.raise_uncaught_exception(exc)
  File "/Users/dealshare/anaconda3/lib/python3.11/site-packages/rest_framework/views.py", line 486, in raise_uncaught_exception
    raise exc
  File "/Users/dealshare/anaconda3/lib/python3.11/site-packages/rest_framework/views.py", line 512, in dispatch
    response = handler(request, *args, **kwargs)
               ^^^^^^^^^^^^^^^^^^^^^^^^^^^^^^^^^
  File "/Users/dealshare/anaconda3/lib/python3.11/site-packages/rest_framework/mixins.py", line 19, in create
    self.perform_create(serializer)
  File "/Users/dealshare/Documents/GitHub/kamna-erp/erp/cv_hub/api/views.py", line 160, in perform_create
    serializer.save(created_by=self.request.user if self.request.user.is_authenticated else None)
  File "/Users/dealshare/anaconda3/lib/python3.11/site-packages/rest_framework/serializers.py", line 210, in save
    self.instance = self.create(validated_data)
                    ^^^^^^^^^^^^^^^^^^^^^^^^^^^
  File "/Users/dealshare/anaconda3/lib/python3.11/site-packages/rest_framework/serializers.py", line 1010, in create
    raise TypeError(msg)
TypeError: Got a `TypeError` when calling `CvHubAddress.objects.create()`. This may be because you have a writable field on the serializer class that is not a valid argument to `CvHubAddress.objects.create()`. You may need to make the field read-only, or override the CvHubAddressSerializer.create() method to handle this correctly.
Original exception was:
 Traceback (most recent call last):
  File "/Users/dealshare/anaconda3/lib/python3.11/site-packages/rest_framework/serializers.py", line 991, in create
    instance = ModelClass._default_manager.create(**validated_data)
               ^^^^^^^^^^^^^^^^^^^^^^^^^^^^^^^^^^^^^^^^^^^^^^^^^^^^
  File "/Users/dealshare/anaconda3/lib/python3.11/site-packages/django/db/models/manager.py", line 87, in manager_method
    return getattr(self.get_queryset(), name)(*args, **kwargs)
           ^^^^^^^^^^^^^^^^^^^^^^^^^^^^^^^^^^^^^^^^^^^^^^^^^^^
  File "/Users/dealshare/anaconda3/lib/python3.11/site-packages/django/db/models/query.py", line 661, in create
    obj = self.model(**kwargs)
          ^^^^^^^^^^^^^^^^^^^^
  File "/Users/dealshare/anaconda3/lib/python3.11/site-packages/django/db/models/base.py", line 569, in __init__
    raise TypeError(
TypeError: CvHubAddress() got unexpected keyword arguments: 'created_by'

[12/Aug/2025 12:26:15] "POST /api/cv_hub/addresses/ HTTP/1.1" 500 158606
[12/Aug/2025 12:27:05] "GET /app HTTP/1.1" 200 5932
[12/Aug/2025 12:30:00] "GET /app/cv_hub/entries/ HTTP/1.1" 200 36884
[12/Aug/2025 12:30:00] "GET /api/cv_hub/states/ HTTP/1.1" 200 254
[12/Aug/2025 12:30:00] "GET /api/cv_hub/entries/?page=1 HTTP/1.1" 200 3817
[12/Aug/2025 12:30:02] "GET /app/cv_hub/entries/28 HTTP/1.1" 200 45709
[12/Aug/2025 12:30:02] "GET /api/cv_hub/entries/28/ HTTP/1.1" 200 766
[12/Aug/2025 12:30:02] "GET /api/cv_hub/entries/28/history/ HTTP/1.1" 200 246
[12/Aug/2025 12:30:08] "GET /app/cv_hub/entries/28/edit HTTP/1.1" 200 59018
[12/Aug/2025 12:30:08] "GET /api/cv_hub/entries/28/ HTTP/1.1" 200 766
[12/Aug/2025 12:30:25] "GET /app/cv_hub/entries/28/edit HTTP/1.1" 200 59018
[12/Aug/2025 12:30:25] "GET /api/cv_hub/entries/28/ HTTP/1.1" 200 766
[12/Aug/2025 12:30:29] "GET /app/cv_hub/entries/ HTTP/1.1" 200 36884
[12/Aug/2025 12:30:29] "GET /api/cv_hub/states/ HTTP/1.1" 200 254
[12/Aug/2025 12:30:29] "GET /api/cv_hub/entries/?page=1 HTTP/1.1" 200 3817
[12/Aug/2025 12:30:31] "GET /app/cv_hub/entries/28 HTTP/1.1" 200 45709
[12/Aug/2025 12:30:31] "GET /api/cv_hub/entries/28/ HTTP/1.1" 200 766
[12/Aug/2025 12:30:31] "GET /api/cv_hub/entries/28/history/ HTTP/1.1" 200 246
[12/Aug/2025 12:30:37] "GET /app/cv_hub/entries/ HTTP/1.1" 200 36884
[12/Aug/2025 12:30:37] "GET /api/cv_hub/states/ HTTP/1.1" 200 254
[12/Aug/2025 12:30:37] "GET /api/cv_hub/entries/?page=1 HTTP/1.1" 200 3817
/Users/dealshare/Documents/GitHub/kamna-erp/erp/cv_hub/api/views.py changed, reloading.
Performing system checks...

System check identified no issues (0 silenced).
August 12, 2025 - 12:13:23
Django version 5.2.4, using settings 'erp.settings'
Starting development server at http://127.0.0.1:8000/
Quit the server with CONTROL-C.

WARNING: This is a development server. Do not use it in a production setting. Use a production WSGI or ASGI server instead.
For more information on production servers see: https://docs.djangoproject.com/en/5.2/howto/deployment/
Watching for file changes with StatReloader
/Users/dealshare/Documents/GitHub/kamna-erp/erp/cv_hub/api/serializers.py changed, reloading.
Performing system checks...

System check identified no issues (0 silenced).
August 12, 2025 - 12:34:49
Django version 5.2.4, using settings 'erp.settings'
Starting development server at http://127.0.0.1:8000/
Quit the server with CONTROL-C.

WARNING: This is a development server. Do not use it in a production setting. Use a production WSGI or ASGI server instead.
For more information on production servers see: https://docs.djangoproject.com/en/5.2/howto/deployment/
Watching for file changes with StatReloader
[12/Aug/2025 12:36:17] "GET /app/cv_hub/entries/29/edit HTTP/1.1" 200 59018
[12/Aug/2025 12:36:18] "GET /api/cv_hub/entries/29/ HTTP/1.1" 200 405
[12/Aug/2025 12:36:19] "GET /api/cv_hub/states/ HTTP/1.1" 200 254
[12/Aug/2025 12:36:23] "GET /api/cv_hub/cities/?state=1 HTTP/1.1" 200 194
[12/Aug/2025 12:36:29] "POST /api/cv_hub/addresses/ HTTP/1.1" 201 256
[12/Aug/2025 12:36:29] "GET /api/cv_hub/entries/29/ HTTP/1.1" 200 661
[12/Aug/2025 12:36:31] "PATCH /api/cv_hub/addresses/14/ HTTP/1.1" 200 256
[12/Aug/2025 12:36:31] "GET /api/cv_hub/entries/29/ HTTP/1.1" 200 661
[12/Aug/2025 12:36:35] "GET /api/cv_hub/states/ HTTP/1.1" 200 254
[12/Aug/2025 12:36:52] "GET /api/cv_hub/cities/?state=1 HTTP/1.1" 200 194
[12/Aug/2025 12:36:52] "GET /api/cv_hub/cities/?state=1 HTTP/1.1" 200 194
Bad Request: /api/cv_hub/addresses/
[12/Aug/2025 12:36:54] "POST /api/cv_hub/addresses/ HTTP/1.1" 400 44
[12/Aug/2025 12:37:01] "POST /api/cv_hub/addresses/ HTTP/1.1" 201 264
[12/Aug/2025 12:37:01] "GET /api/cv_hub/entries/29/ HTTP/1.1" 200 927
[12/Aug/2025 12:37:09] "PATCH /api/cv_hub/entries/29/ HTTP/1.1" 200 357
[12/Aug/2025 12:37:09] "GET /app/cv_hub/entries/29 HTTP/1.1" 200 45709
[12/Aug/2025 12:37:09] "GET /api/cv_hub/entries/29/ HTTP/1.1" 200 927
[12/Aug/2025 12:37:09] "GET /api/cv_hub/entries/29/history/ HTTP/1.1" 200 592
[12/Aug/2025 12:37:20] "GET /app/cv_hub/entries/29/edit HTTP/1.1" 200 59018
[12/Aug/2025 12:37:20] "GET /api/cv_hub/entries/29/ HTTP/1.1" 200 927
[12/Aug/2025 12:37:28] "PATCH /api/cv_hub/entries/29/ HTTP/1.1" 200 357
[12/Aug/2025 12:37:28] "GET /app/cv_hub/entries/29 HTTP/1.1" 200 45709
[12/Aug/2025 12:37:28] "GET /api/cv_hub/entries/29/ HTTP/1.1" 200 927
[12/Aug/2025 12:37:28] "GET /api/cv_hub/entries/29/history/ HTTP/1.1" 200 709
[12/Aug/2025 12:37:30] "GET /app/cv_hub/entries/29/edit HTTP/1.1" 200 59018
[12/Aug/2025 12:37:30] "GET /api/cv_hub/entries/29/ HTTP/1.1" 200 927
[12/Aug/2025 12:37:36] "PATCH /api/cv_hub/addresses/15/ HTTP/1.1" 200 264
[12/Aug/2025 12:37:36] "GET /api/cv_hub/entries/29/ HTTP/1.1" 200 927
[12/Aug/2025 12:37:39] "PATCH /api/cv_hub/addresses/15/ HTTP/1.1" 200 265
[12/Aug/2025 12:37:39] "GET /api/cv_hub/entries/29/ HTTP/1.1" 200 928
[12/Aug/2025 12:37:42] "PATCH /api/cv_hub/addresses/14/ HTTP/1.1" 200 256
[12/Aug/2025 12:37:42] "GET /api/cv_hub/entries/29/ HTTP/1.1" 200 927
[12/Aug/2025 12:37:44] "PATCH /api/cv_hub/entries/29/ HTTP/1.1" 200 357
[12/Aug/2025 12:37:44] "GET /app/cv_hub/entries/29 HTTP/1.1" 200 45709
[12/Aug/2025 12:37:44] "GET /api/cv_hub/entries/29/ HTTP/1.1" 200 927
[12/Aug/2025 12:37:44] "GET /api/cv_hub/entries/29/history/ HTTP/1.1" 200 1183
[12/Aug/2025 12:37:47] "GET /app/cv_hub/entries/29/edit HTTP/1.1" 200 59018
[12/Aug/2025 12:37:47] "GET /api/cv_hub/entries/29/ HTTP/1.1" 200 927
[12/Aug/2025 12:38:22] "GET /api/cv_hub/entries/29/history/ HTTP/1.1" 200 1183
